2025-04-04 07:46:39,769 - INFO - Đang khởi tạo WebDriver...
2025-04-04 07:46:39,770 - INFO - ====== WebDriver manager ======
2025-04-04 07:46:39,873 - INFO - Get LATEST chromedriver version for google-chrome
2025-04-04 07:46:39,890 - INFO - Get LATEST chromedriver version for google-chrome
2025-04-04 07:46:39,908 - INFO - There is no [linux64] chromedriver "135.0.7049.42" for browser google-chrome "135.0.7049" in cache
2025-04-04 07:46:39,908 - INFO - Get LATEST chromedriver version for google-chrome
2025-04-04 07:46:39,978 - INFO - WebDriver version 135.0.7049.42 selected
2025-04-04 07:46:39,985 - INFO - Modern chrome version https://storage.googleapis.com/chrome-for-testing-public/135.0.7049.42/linux64/chromedriver-linux64.zip
2025-04-04 07:46:39,985 - INFO - About to download new driver from https://storage.googleapis.com/chrome-for-testing-public/135.0.7049.42/linux64/chromedriver-linux64.zip
2025-04-04 07:46:39,999 - INFO - Driver downloading response is 200
2025-04-04 07:46:40,070 - INFO - Get LATEST chromedriver version for google-chrome
2025-04-04 07:46:40,256 - INFO - Driver has been saved in cache [/home/tthau/.wdm/drivers/chromedriver/linux64/135.0.7049.42]
2025-04-04 07:46:40,631 - INFO - Đang đăng nhập vào Google...
2025-04-04 07:46:41,515 - INFO - Đang nhập mật khẩu...
2025-04-04 07:47:01,575 - ERROR - Lỗi không xác định: Message: 
Stacktrace:
#0 0x5ff693164e6a <unknown>
#1 0x5ff692c16640 <unknown>
#2 0x5ff692c67b5a <unknown>
#3 0x5ff692c67d51 <unknown>
#4 0x5ff692cb6344 <unknown>
#5 0x5ff692c8d77d <unknown>
#6 0x5ff692cb37b5 <unknown>
#7 0x5ff692c8d523 <unknown>
#8 0x5ff692c59ef3 <unknown>
#9 0x5ff692c5ab51 <unknown>
#10 0x5ff693129d2b <unknown>
#11 0x5ff69312dc01 <unknown>
#12 0x5ff693111512 <unknown>
#13 0x5ff69312e774 <unknown>
#14 0x5ff6930f590f <unknown>
#15 0x5ff693152fb8 <unknown>
#16 0x5ff693153196 <unknown>
#17 0x5ff693163cb6 <unknown>
#18 0x76ae19094ac3 <unknown>

2025-04-04 07:47:01,643 - INFO - Đã đóng WebDriver
2025-04-04 07:53:23,380 - INFO - Đang khởi tạo WebDriver...
2025-04-04 07:53:23,380 - INFO - ====== WebDriver manager ======
2025-04-04 07:53:23,484 - INFO - Get LATEST chromedriver version for google-chrome
2025-04-04 07:53:23,503 - INFO - Get LATEST chromedriver version for google-chrome
2025-04-04 07:53:23,520 - INFO - Driver [/home/tthau/.wdm/drivers/chromedriver/linux64/135.0.7049.42/chromedriver-linux64/chromedriver] found in cache
2025-04-04 07:53:23,827 - INFO - Đang đăng nhập vào Google...
2025-04-04 07:53:24,677 - INFO - Đang nhập mật khẩu...
2025-04-04 07:53:44,995 - ERROR - Lỗi không xác định: Message: 
Stacktrace:
#0 0x5b40d0ed5e6a <unknown>
#1 0x5b40d0987640 <unknown>
#2 0x5b40d09d8b5a <unknown>
#3 0x5b40d09d8d51 <unknown>
#4 0x5b40d0a27344 <unknown>
#5 0x5b40d09fe77d <unknown>
#6 0x5b40d0a247b5 <unknown>
#7 0x5b40d09fe523 <unknown>
#8 0x5b40d09caef3 <unknown>
#9 0x5b40d09cbb51 <unknown>
#10 0x5b40d0e9ad2b <unknown>
#11 0x5b40d0e9ec01 <unknown>
#12 0x5b40d0e82512 <unknown>
#13 0x5b40d0e9f774 <unknown>
#14 0x5b40d0e6690f <unknown>
#15 0x5b40d0ec3fb8 <unknown>
#16 0x5b40d0ec4196 <unknown>
#17 0x5b40d0ed4cb6 <unknown>
#18 0x7fbc13a94ac3 <unknown>

2025-04-04 07:53:45,058 - INFO - Đã đóng WebDriver
2025-04-04 08:01:53,042 - INFO - Đang khởi tạo WebDriver...
2025-04-04 08:01:53,042 - INFO - ====== WebDriver manager ======
2025-04-04 08:01:53,127 - INFO - Get LATEST chromedriver version for google-chrome
2025-04-04 08:01:53,144 - INFO - Get LATEST chromedriver version for google-chrome
2025-04-04 08:01:53,159 - INFO - Driver [/home/tthau/.wdm/drivers/chromedriver/linux64/135.0.7049.42/chromedriver-linux64/chromedriver] found in cache
2025-04-04 08:01:53,464 - INFO - Đang đăng nhập vào Google...
2025-04-04 08:01:54,495 - INFO - Đang tìm trường nhập email...
2025-04-04 08:01:54,533 - INFO - Tìm thấy input email bằng ID
2025-04-04 08:01:55,211 - INFO - Đã click nút Next sau khi nhập email
2025-04-04 08:01:55,211 - INFO - Đang chờ màn hình nhập mật khẩu...
2025-04-04 08:02:30,500 - INFO - Không tìm thấy input password bằng Name, thử cách khác...
2025-04-04 08:03:00,690 - INFO - Không tìm thấy input password bằng XPath type
2025-04-04 08:03:30,907 - INFO - Không tìm thấy input password bằng aria-label
2025-04-04 08:03:30,928 - INFO - Tìm thấy 8 input elements trên trang
2025-04-04 08:03:31,000 - INFO - Input #0: {'id': 'identifierId', 'name': 'identifier', 'type': 'email', 'aria-label': 'Email or phone', 'placeholder': ''}
2025-04-04 08:03:31,029 - INFO - Input #1: {'id': '', 'name': 'hiddenPassword', 'type': 'password', 'aria-label': None, 'placeholder': ''}
2025-04-04 08:03:31,058 - INFO - Input #2: {'id': 'ca', 'name': 'ca', 'type': 'text', 'aria-label': 'Type the text you hear or see', 'placeholder': ''}
2025-04-04 08:03:31,084 - INFO - Input #3: {'id': 'ct', 'name': 'ct', 'type': 'hidden', 'aria-label': None, 'placeholder': ''}
2025-04-04 08:03:31,110 - INFO - Input #4: {'id': '', 'name': 'usi', 'type': 'hidden', 'aria-label': None, 'placeholder': ''}
2025-04-04 08:03:31,137 - INFO - Input #5: {'id': '', 'name': 'domain', 'type': 'hidden', 'aria-label': None, 'placeholder': ''}
2025-04-04 08:03:31,166 - INFO - Input #6: {'id': '', 'name': 'region', 'type': 'hidden', 'aria-label': None, 'placeholder': ''}
2025-04-04 08:03:31,193 - INFO - Input #7: {'id': 'fidoUserHandle', 'name': '', 'type': 'hidden', 'aria-label': None, 'placeholder': ''}
2025-04-04 08:03:31,204 - INFO - Sử dụng input có type=password
2025-04-04 08:03:31,230 - ERROR - Lỗi khi nhập mật khẩu: Message: element not interactable
  (Session info: chrome=135.0.7049.52)
Stacktrace:
#0 0x60aaaa635e6a <unknown>
#1 0x60aaaa0e7493 <unknown>
#2 0x60aaaa12eff2 <unknown>
#3 0x60aaaa15e752 <unknown>
#4 0x60aaaa12c4fa <unknown>
#5 0x60aaaa15e91e <unknown>
#6 0x60aaaa1847b5 <unknown>
#7 0x60aaaa15e523 <unknown>
#8 0x60aaaa12aef3 <unknown>
#9 0x60aaaa12bb51 <unknown>
#10 0x60aaaa5fad2b <unknown>
#11 0x60aaaa5fec01 <unknown>
#12 0x60aaaa5e2512 <unknown>
#13 0x60aaaa5ff774 <unknown>
#14 0x60aaaa5c690f <unknown>
#15 0x60aaaa623fb8 <unknown>
#16 0x60aaaa624196 <unknown>
#17 0x60aaaa634cb6 <unknown>
#18 0x77414bc94ac3 <unknown>

2025-04-04 08:03:31,371 - INFO - Chờ đăng nhập hoàn tất...
2025-04-04 08:03:41,528 - INFO - Đang truy cập album: https://photos.google.com/u/4/share/AF1QipNtdMlRS1ongp0jV4HOZ1_HNSFeJQujLVX6Z5zqWMYxj3RIZ62PXehf8JuZtwmlIA
2025-04-04 08:03:52,240 - INFO - Đã chụp ảnh màn hình trang album
2025-04-04 08:03:52,240 - INFO - Tìm nút 'Lưu ảnh'...
2025-04-04 08:03:52,254 - INFO - Tìm thấy 0 buttons trên trang album
2025-04-04 08:03:52,280 - ERROR - Không tìm thấy nút 'Lưu ảnh'
2025-04-04 08:03:52,286 - ERROR - Không tìm thấy nút 'Lưu ảnh' bằng JavaScript
2025-04-04 08:03:52,286 - INFO - Hoàn thành thao tác!
2025-04-04 08:03:53,365 - INFO - Đã đóng WebDriver
2025-04-04 08:04:52,205 - INFO - Đang khởi tạo WebDriver...
2025-04-04 08:04:52,205 - INFO - ====== WebDriver manager ======
2025-04-04 08:04:52,288 - INFO - Get LATEST chromedriver version for google-chrome
2025-04-04 08:04:52,306 - INFO - Get LATEST chromedriver version for google-chrome
2025-04-04 08:04:52,338 - INFO - Driver [/home/tthau/.wdm/drivers/chromedriver/linux64/135.0.7049.42/chromedriver-linux64/chromedriver] found in cache
2025-04-04 08:04:52,661 - INFO - Đang đăng nhập vào Google...
2025-04-04 08:04:53,786 - INFO - Đang tìm trường nhập email...
2025-04-04 08:04:53,838 - INFO - Tìm thấy input email bằng ID
2025-04-04 08:04:54,556 - INFO - Đã click nút Next sau khi nhập email
2025-04-04 08:04:54,556 - INFO - Đang chờ màn hình nhập mật khẩu...
2025-04-04 08:04:59,736 - INFO - Tìm thấy input password bằng Name
2025-04-04 08:05:00,240 - INFO - Đã click nút Next sau khi nhập mật khẩu
2025-04-04 08:05:00,240 - INFO - Chờ đăng nhập hoàn tất...
2025-04-04 08:05:10,412 - INFO - Đang truy cập album: https://photos.google.com/u/4/share/AF1QipNtdMlRS1ongp0jV4HOZ1_HNSFeJQujLVX6Z5zqWMYxj3RIZ62PXehf8JuZtwmlIA
2025-04-04 08:05:20,982 - INFO - Đã chụp ảnh màn hình trang album
2025-04-04 08:05:20,982 - INFO - Tìm nút 'Lưu ảnh'...
2025-04-04 08:05:21,008 - INFO - Tìm thấy 0 buttons trên trang album
2025-04-04 08:05:21,049 - ERROR - Không tìm thấy nút 'Lưu ảnh'
2025-04-04 08:05:21,068 - ERROR - Không tìm thấy nút 'Lưu ảnh' bằng JavaScript
2025-04-04 08:05:21,068 - INFO - Hoàn thành thao tác!
2025-04-04 08:05:21,137 - INFO - Đã đóng WebDriver
2025-04-04 08:07:56,329 - INFO - Đang khởi tạo WebDriver...
2025-04-04 08:07:56,330 - INFO - ====== WebDriver manager ======
2025-04-04 08:07:56,461 - INFO - Get LATEST chromedriver version for google-chrome
2025-04-04 08:07:56,480 - INFO - Get LATEST chromedriver version for google-chrome
2025-04-04 08:07:56,495 - INFO - Driver [/home/tthau/.wdm/drivers/chromedriver/linux64/135.0.7049.42/chromedriver-linux64/chromedriver] found in cache
2025-04-04 08:07:56,848 - INFO - Đang đăng nhập vào Google...
2025-04-04 08:07:57,959 - INFO - Đang tìm trường nhập email...
2025-04-04 08:07:57,996 - INFO - Tìm thấy input email bằng ID
2025-04-04 08:07:58,724 - INFO - Đã click nút Next sau khi nhập email
2025-04-04 08:07:58,724 - INFO - Đang chờ màn hình nhập mật khẩu...
2025-04-04 08:08:34,198 - INFO - Không tìm thấy input password bằng Name, thử cách khác...
2025-04-04 08:09:04,492 - INFO - Không tìm thấy input password bằng XPath type
2025-04-04 08:09:08,919 - INFO - Không tìm thấy input password bằng aria-label
2025-04-04 08:09:08,920 - ERROR - Lỗi khi nhập mật khẩu: ('Connection aborted.', RemoteDisconnected('Remote end closed connection without response'))
2025-04-04 08:09:08,922 - WARNING - Retrying (Retry(total=2, connect=None, read=None, redirect=None, status=None)) after connection broken by 'NewConnectionError('<urllib3.connection.HTTPConnection object at 0x72a1d6728df0>: Failed to establish a new connection: [Errno 111] Connection refused')': /session/ad9ad6653c769bcc97ddefb4b89ab001/screenshot
2025-04-04 08:09:08,922 - WARNING - Retrying (Retry(total=1, connect=None, read=None, redirect=None, status=None)) after connection broken by 'NewConnectionError('<urllib3.connection.HTTPConnection object at 0x72a1d67288b0>: Failed to establish a new connection: [Errno 111] Connection refused')': /session/ad9ad6653c769bcc97ddefb4b89ab001/screenshot
2025-04-04 08:09:08,923 - WARNING - Retrying (Retry(total=0, connect=None, read=None, redirect=None, status=None)) after connection broken by 'NewConnectionError('<urllib3.connection.HTTPConnection object at 0x72a1d6728f70>: Failed to establish a new connection: [Errno 111] Connection refused')': /session/ad9ad6653c769bcc97ddefb4b89ab001/screenshot
2025-04-04 08:09:08,923 - ERROR - Lỗi không xác định: HTTPConnectionPool(host='localhost', port=50807): Max retries exceeded with url: /session/ad9ad6653c769bcc97ddefb4b89ab001/screenshot (Caused by NewConnectionError('<urllib3.connection.HTTPConnection object at 0x72a1d67290c0>: Failed to establish a new connection: [Errno 111] Connection refused'))
2025-04-04 08:09:08,938 - ERROR - Traceback (most recent call last):
  File "/home/tthau/.local/lib/python3.10/site-packages/urllib3/connectionpool.py", line 789, in urlopen
    response = self._make_request(
  File "/home/tthau/.local/lib/python3.10/site-packages/urllib3/connectionpool.py", line 536, in _make_request
    response = conn.getresponse()
  File "/home/tthau/.local/lib/python3.10/site-packages/urllib3/connection.py", line 464, in getresponse
    httplib_response = super().getresponse()
  File "/usr/lib/python3.10/http/client.py", line 1375, in getresponse
    response.begin()
  File "/usr/lib/python3.10/http/client.py", line 318, in begin
    version, status, reason = self._read_status()
  File "/usr/lib/python3.10/http/client.py", line 287, in _read_status
    raise RemoteDisconnected("Remote end closed connection without"
http.client.RemoteDisconnected: Remote end closed connection without response

During handling of the above exception, another exception occurred:

Traceback (most recent call last):
  File "/home/tthau/PROJECT/BKGGPT/clone_album.py", line 197, in <module>
    all_inputs = driver.find_elements(By.TAG_NAME, "input")
  File "/home/tthau/.local/lib/python3.10/site-packages/selenium/webdriver/remote/webdriver.py", line 936, in find_elements
    return self.execute(Command.FIND_ELEMENTS, {"using": by, "value": value})["value"] or []
  File "/home/tthau/.local/lib/python3.10/site-packages/selenium/webdriver/remote/webdriver.py", line 427, in execute
    response = self.command_executor.execute(driver_command, params)
  File "/home/tthau/.local/lib/python3.10/site-packages/selenium/webdriver/remote/remote_connection.py", line 404, in execute
    return self._request(command_info[0], url, body=data)
  File "/home/tthau/.local/lib/python3.10/site-packages/selenium/webdriver/remote/remote_connection.py", line 428, in _request
    response = self._conn.request(method, url, body=body, headers=headers, timeout=self._client_config.timeout)
  File "/home/tthau/.local/lib/python3.10/site-packages/urllib3/_request_methods.py", line 144, in request
    return self.request_encode_body(
  File "/home/tthau/.local/lib/python3.10/site-packages/urllib3/_request_methods.py", line 279, in request_encode_body
    return self.urlopen(method, url, **extra_kw)
  File "/home/tthau/.local/lib/python3.10/site-packages/urllib3/poolmanager.py", line 443, in urlopen
    response = conn.urlopen(method, u.request_uri, **kw)
  File "/home/tthau/.local/lib/python3.10/site-packages/urllib3/connectionpool.py", line 843, in urlopen
    retries = retries.increment(
  File "/home/tthau/.local/lib/python3.10/site-packages/urllib3/util/retry.py", line 474, in increment
    raise reraise(type(error), error, _stacktrace)
  File "/home/tthau/.local/lib/python3.10/site-packages/urllib3/util/util.py", line 38, in reraise
    raise value.with_traceback(tb)
  File "/home/tthau/.local/lib/python3.10/site-packages/urllib3/connectionpool.py", line 789, in urlopen
    response = self._make_request(
  File "/home/tthau/.local/lib/python3.10/site-packages/urllib3/connectionpool.py", line 536, in _make_request
    response = conn.getresponse()
  File "/home/tthau/.local/lib/python3.10/site-packages/urllib3/connection.py", line 464, in getresponse
    httplib_response = super().getresponse()
  File "/usr/lib/python3.10/http/client.py", line 1375, in getresponse
    response.begin()
  File "/usr/lib/python3.10/http/client.py", line 318, in begin
    version, status, reason = self._read_status()
  File "/usr/lib/python3.10/http/client.py", line 287, in _read_status
    raise RemoteDisconnected("Remote end closed connection without"
urllib3.exceptions.ProtocolError: ('Connection aborted.', RemoteDisconnected('Remote end closed connection without response'))

During handling of the above exception, another exception occurred:

Traceback (most recent call last):
  File "/home/tthau/.local/lib/python3.10/site-packages/urllib3/connection.py", line 196, in _new_conn
    sock = connection.create_connection(
  File "/home/tthau/.local/lib/python3.10/site-packages/urllib3/util/connection.py", line 85, in create_connection
    raise err
  File "/home/tthau/.local/lib/python3.10/site-packages/urllib3/util/connection.py", line 73, in create_connection
    sock.connect(sa)
ConnectionRefusedError: [Errno 111] Connection refused

The above exception was the direct cause of the following exception:

Traceback (most recent call last):
  File "/home/tthau/.local/lib/python3.10/site-packages/urllib3/connectionpool.py", line 789, in urlopen
    response = self._make_request(
  File "/home/tthau/.local/lib/python3.10/site-packages/urllib3/connectionpool.py", line 495, in _make_request
    conn.request(
  File "/home/tthau/.local/lib/python3.10/site-packages/urllib3/connection.py", line 398, in request
    self.endheaders()
  File "/usr/lib/python3.10/http/client.py", line 1278, in endheaders
    self._send_output(message_body, encode_chunked=encode_chunked)
  File "/usr/lib/python3.10/http/client.py", line 1038, in _send_output
    self.send(msg)
  File "/usr/lib/python3.10/http/client.py", line 976, in send
    self.connect()
  File "/home/tthau/.local/lib/python3.10/site-packages/urllib3/connection.py", line 236, in connect
    self.sock = self._new_conn()
  File "/home/tthau/.local/lib/python3.10/site-packages/urllib3/connection.py", line 211, in _new_conn
    raise NewConnectionError(
urllib3.exceptions.NewConnectionError: <urllib3.connection.HTTPConnection object at 0x72a1d67290c0>: Failed to establish a new connection: [Errno 111] Connection refused

The above exception was the direct cause of the following exception:

Traceback (most recent call last):
  File "/home/tthau/PROJECT/BKGGPT/clone_album.py", line 254, in <module>
    driver.save_screenshot("password_input_error.png")
  File "/home/tthau/.local/lib/python3.10/site-packages/selenium/webdriver/remote/webdriver.py", line 994, in save_screenshot
    return self.get_screenshot_as_file(filename)
  File "/home/tthau/.local/lib/python3.10/site-packages/selenium/webdriver/remote/webdriver.py", line 969, in get_screenshot_as_file
    png = self.get_screenshot_as_png()
  File "/home/tthau/.local/lib/python3.10/site-packages/selenium/webdriver/remote/webdriver.py", line 1003, in get_screenshot_as_png
    return b64decode(self.get_screenshot_as_base64().encode("ascii"))
  File "/home/tthau/.local/lib/python3.10/site-packages/selenium/webdriver/remote/webdriver.py", line 1013, in get_screenshot_as_base64
    return self.execute(Command.SCREENSHOT)["value"]
  File "/home/tthau/.local/lib/python3.10/site-packages/selenium/webdriver/remote/webdriver.py", line 427, in execute
    response = self.command_executor.execute(driver_command, params)
  File "/home/tthau/.local/lib/python3.10/site-packages/selenium/webdriver/remote/remote_connection.py", line 404, in execute
    return self._request(command_info[0], url, body=data)
  File "/home/tthau/.local/lib/python3.10/site-packages/selenium/webdriver/remote/remote_connection.py", line 428, in _request
    response = self._conn.request(method, url, body=body, headers=headers, timeout=self._client_config.timeout)
  File "/home/tthau/.local/lib/python3.10/site-packages/urllib3/_request_methods.py", line 136, in request
    return self.request_encode_url(
  File "/home/tthau/.local/lib/python3.10/site-packages/urllib3/_request_methods.py", line 183, in request_encode_url
    return self.urlopen(method, url, **extra_kw)
  File "/home/tthau/.local/lib/python3.10/site-packages/urllib3/poolmanager.py", line 443, in urlopen
    response = conn.urlopen(method, u.request_uri, **kw)
  File "/home/tthau/.local/lib/python3.10/site-packages/urllib3/connectionpool.py", line 873, in urlopen
    return self.urlopen(
  File "/home/tthau/.local/lib/python3.10/site-packages/urllib3/connectionpool.py", line 873, in urlopen
    return self.urlopen(
  File "/home/tthau/.local/lib/python3.10/site-packages/urllib3/connectionpool.py", line 873, in urlopen
    return self.urlopen(
  File "/home/tthau/.local/lib/python3.10/site-packages/urllib3/connectionpool.py", line 843, in urlopen
    retries = retries.increment(
  File "/home/tthau/.local/lib/python3.10/site-packages/urllib3/util/retry.py", line 519, in increment
    raise MaxRetryError(_pool, url, reason) from reason  # type: ignore[arg-type]
urllib3.exceptions.MaxRetryError: HTTPConnectionPool(host='localhost', port=50807): Max retries exceeded with url: /session/ad9ad6653c769bcc97ddefb4b89ab001/screenshot (Caused by NewConnectionError('<urllib3.connection.HTTPConnection object at 0x72a1d67290c0>: Failed to establish a new connection: [Errno 111] Connection refused'))

2025-04-04 08:09:08,940 - WARNING - Retrying (Retry(total=2, connect=None, read=None, redirect=None, status=None)) after connection broken by 'NewConnectionError('<urllib3.connection.HTTPConnection object at 0x72a1d6729540>: Failed to establish a new connection: [Errno 111] Connection refused')': /session/ad9ad6653c769bcc97ddefb4b89ab001/screenshot
2025-04-04 08:09:08,940 - WARNING - Retrying (Retry(total=1, connect=None, read=None, redirect=None, status=None)) after connection broken by 'NewConnectionError('<urllib3.connection.HTTPConnection object at 0x72a1d67296c0>: Failed to establish a new connection: [Errno 111] Connection refused')': /session/ad9ad6653c769bcc97ddefb4b89ab001/screenshot
2025-04-04 08:09:08,941 - WARNING - Retrying (Retry(total=0, connect=None, read=None, redirect=None, status=None)) after connection broken by 'NewConnectionError('<urllib3.connection.HTTPConnection object at 0x72a1d6729810>: Failed to establish a new connection: [Errno 111] Connection refused')': /session/ad9ad6653c769bcc97ddefb4b89ab001/screenshot
2025-04-04 08:09:08,942 - WARNING - Retrying (Retry(total=2, connect=None, read=None, redirect=None, status=None)) after connection broken by 'NewConnectionError('<urllib3.connection.HTTPConnection object at 0x72a1d6729ae0>: Failed to establish a new connection: [Errno 111] Connection refused')': /session/ad9ad6653c769bcc97ddefb4b89ab001
2025-04-04 08:09:08,943 - WARNING - Retrying (Retry(total=1, connect=None, read=None, redirect=None, status=None)) after connection broken by 'NewConnectionError('<urllib3.connection.HTTPConnection object at 0x72a1d6729c30>: Failed to establish a new connection: [Errno 111] Connection refused')': /session/ad9ad6653c769bcc97ddefb4b89ab001
2025-04-04 08:09:08,946 - WARNING - Retrying (Retry(total=0, connect=None, read=None, redirect=None, status=None)) after connection broken by 'NewConnectionError('<urllib3.connection.HTTPConnection object at 0x72a1d6729d80>: Failed to establish a new connection: [Errno 111] Connection refused')': /session/ad9ad6653c769bcc97ddefb4b89ab001
2025-04-04 08:09:08,950 - INFO - Đã đóng WebDriver
2025-04-04 09:37:30,459 - INFO - Đang khởi tạo WebDriver...
2025-04-04 09:37:30,459 - INFO - ====== WebDriver manager ======
2025-04-04 09:37:30,590 - INFO - Get LATEST chromedriver version for google-chrome
2025-04-04 09:37:30,619 - INFO - Get LATEST chromedriver version for google-chrome
2025-04-04 09:37:30,636 - INFO - Driver [/home/tthau/.wdm/drivers/chromedriver/linux64/135.0.7049.42/chromedriver-linux64/chromedriver] found in cache
2025-04-04 09:37:32,402 - INFO - Đang đăng nhập vào Google...
2025-04-04 09:37:37,661 - INFO - Đang tìm trường nhập email...
2025-04-04 09:37:37,676 - INFO - Tìm thấy input email bằng ID
2025-04-04 09:37:39,507 - INFO - Đang nhập email: trunghautran0102travel@gmail.com
2025-04-04 09:37:49,375 - INFO - Đã tìm thấy nút Next, chuẩn bị click...
2025-04-04 09:37:50,513 - INFO - Đã click nút Next sau khi nhập email
2025-04-04 09:37:55,272 - INFO - Đang chờ màn hình nhập mật khẩu...
2025-04-04 09:38:14,324 - INFO - Không tìm thấy input password bằng Name, thử cách khác...
2025-04-04 09:38:14,325 - INFO - Không tìm thấy input password bằng XPath type
2025-04-04 09:38:14,327 - WARNING - Retrying (Retry(total=2, connect=None, read=None, redirect=None, status=None)) after connection broken by 'NewConnectionError('<urllib3.connection.HTTPConnection object at 0x741d735d2e60>: Failed to establish a new connection: [Errno 111] Connection refused')': /session/5c3037b876a106c9b1369a9069e33b8d/element
2025-04-04 09:38:14,327 - WARNING - Retrying (Retry(total=1, connect=None, read=None, redirect=None, status=None)) after connection broken by 'NewConnectionError('<urllib3.connection.HTTPConnection object at 0x741d735d3070>: Failed to establish a new connection: [Errno 111] Connection refused')': /session/5c3037b876a106c9b1369a9069e33b8d/element
2025-04-04 09:38:14,329 - WARNING - Retrying (Retry(total=0, connect=None, read=None, redirect=None, status=None)) after connection broken by 'NewConnectionError('<urllib3.connection.HTTPConnection object at 0x741d735d3520>: Failed to establish a new connection: [Errno 111] Connection refused')': /session/5c3037b876a106c9b1369a9069e33b8d/element
2025-04-04 09:38:14,330 - INFO - Không tìm thấy input password bằng aria-label
2025-04-04 09:38:14,330 - WARNING - Retrying (Retry(total=2, connect=None, read=None, redirect=None, status=None)) after connection broken by 'NewConnectionError('<urllib3.connection.HTTPConnection object at 0x741d735d3760>: Failed to establish a new connection: [Errno 111] Connection refused')': /session/5c3037b876a106c9b1369a9069e33b8d/elements
2025-04-04 09:38:14,331 - WARNING - Retrying (Retry(total=1, connect=None, read=None, redirect=None, status=None)) after connection broken by 'NewConnectionError('<urllib3.connection.HTTPConnection object at 0x741d735d3940>: Failed to establish a new connection: [Errno 111] Connection refused')': /session/5c3037b876a106c9b1369a9069e33b8d/elements
2025-04-04 09:38:14,332 - WARNING - Retrying (Retry(total=0, connect=None, read=None, redirect=None, status=None)) after connection broken by 'NewConnectionError('<urllib3.connection.HTTPConnection object at 0x741d735d3b50>: Failed to establish a new connection: [Errno 111] Connection refused')': /session/5c3037b876a106c9b1369a9069e33b8d/elements
2025-04-04 09:38:14,333 - ERROR - Lỗi khi nhập mật khẩu: HTTPConnectionPool(host='localhost', port=33723): Max retries exceeded with url: /session/5c3037b876a106c9b1369a9069e33b8d/elements (Caused by NewConnectionError('<urllib3.connection.HTTPConnection object at 0x741d735d3d60>: Failed to establish a new connection: [Errno 111] Connection refused'))
2025-04-04 09:38:14,334 - WARNING - Retrying (Retry(total=2, connect=None, read=None, redirect=None, status=None)) after connection broken by 'NewConnectionError('<urllib3.connection.HTTPConnection object at 0x741d735d3fd0>: Failed to establish a new connection: [Errno 111] Connection refused')': /session/5c3037b876a106c9b1369a9069e33b8d/screenshot
2025-04-04 09:38:14,334 - WARNING - Retrying (Retry(total=1, connect=None, read=None, redirect=None, status=None)) after connection broken by 'NewConnectionError('<urllib3.connection.HTTPConnection object at 0x741d7344c190>: Failed to establish a new connection: [Errno 111] Connection refused')': /session/5c3037b876a106c9b1369a9069e33b8d/screenshot
2025-04-04 09:38:14,335 - WARNING - Retrying (Retry(total=0, connect=None, read=None, redirect=None, status=None)) after connection broken by 'NewConnectionError('<urllib3.connection.HTTPConnection object at 0x741d7344c310>: Failed to establish a new connection: [Errno 111] Connection refused')': /session/5c3037b876a106c9b1369a9069e33b8d/screenshot
2025-04-04 09:38:14,335 - ERROR - Lỗi không xác định: HTTPConnectionPool(host='localhost', port=33723): Max retries exceeded with url: /session/5c3037b876a106c9b1369a9069e33b8d/screenshot (Caused by NewConnectionError('<urllib3.connection.HTTPConnection object at 0x741d7344c490>: Failed to establish a new connection: [Errno 111] Connection refused'))
2025-04-04 09:38:14,340 - ERROR - Traceback (most recent call last):
  File "/home/tthau/.local/lib/python3.10/site-packages/urllib3/connection.py", line 196, in _new_conn
    sock = connection.create_connection(
  File "/home/tthau/.local/lib/python3.10/site-packages/urllib3/util/connection.py", line 85, in create_connection
    raise err
  File "/home/tthau/.local/lib/python3.10/site-packages/urllib3/util/connection.py", line 73, in create_connection
    sock.connect(sa)
ConnectionRefusedError: [Errno 111] Connection refused

The above exception was the direct cause of the following exception:

Traceback (most recent call last):
  File "/home/tthau/.local/lib/python3.10/site-packages/urllib3/connectionpool.py", line 789, in urlopen
    response = self._make_request(
  File "/home/tthau/.local/lib/python3.10/site-packages/urllib3/connectionpool.py", line 495, in _make_request
    conn.request(
  File "/home/tthau/.local/lib/python3.10/site-packages/urllib3/connection.py", line 398, in request
    self.endheaders()
  File "/usr/lib/python3.10/http/client.py", line 1278, in endheaders
    self._send_output(message_body, encode_chunked=encode_chunked)
  File "/usr/lib/python3.10/http/client.py", line 1038, in _send_output
    self.send(msg)
  File "/usr/lib/python3.10/http/client.py", line 976, in send
    self.connect()
  File "/home/tthau/.local/lib/python3.10/site-packages/urllib3/connection.py", line 236, in connect
    self.sock = self._new_conn()
  File "/home/tthau/.local/lib/python3.10/site-packages/urllib3/connection.py", line 211, in _new_conn
    raise NewConnectionError(
urllib3.exceptions.NewConnectionError: <urllib3.connection.HTTPConnection object at 0x741d735d3d60>: Failed to establish a new connection: [Errno 111] Connection refused

The above exception was the direct cause of the following exception:

Traceback (most recent call last):
  File "/home/tthau/PROJECT/BKGGPT/clone_album.py", line 334, in <module>
    all_inputs = driver.find_elements(By.TAG_NAME, "input")
  File "/home/tthau/.local/lib/python3.10/site-packages/selenium/webdriver/remote/webdriver.py", line 936, in find_elements
    return self.execute(Command.FIND_ELEMENTS, {"using": by, "value": value})["value"] or []
  File "/home/tthau/.local/lib/python3.10/site-packages/selenium/webdriver/remote/webdriver.py", line 427, in execute
    response = self.command_executor.execute(driver_command, params)
  File "/home/tthau/.local/lib/python3.10/site-packages/selenium/webdriver/remote/remote_connection.py", line 404, in execute
    return self._request(command_info[0], url, body=data)
  File "/home/tthau/.local/lib/python3.10/site-packages/selenium/webdriver/remote/remote_connection.py", line 428, in _request
    response = self._conn.request(method, url, body=body, headers=headers, timeout=self._client_config.timeout)
  File "/home/tthau/.local/lib/python3.10/site-packages/urllib3/_request_methods.py", line 144, in request
    return self.request_encode_body(
  File "/home/tthau/.local/lib/python3.10/site-packages/urllib3/_request_methods.py", line 279, in request_encode_body
    return self.urlopen(method, url, **extra_kw)
  File "/home/tthau/.local/lib/python3.10/site-packages/urllib3/poolmanager.py", line 443, in urlopen
    response = conn.urlopen(method, u.request_uri, **kw)
  File "/home/tthau/.local/lib/python3.10/site-packages/urllib3/connectionpool.py", line 873, in urlopen
    return self.urlopen(
  File "/home/tthau/.local/lib/python3.10/site-packages/urllib3/connectionpool.py", line 873, in urlopen
    return self.urlopen(
  File "/home/tthau/.local/lib/python3.10/site-packages/urllib3/connectionpool.py", line 873, in urlopen
    return self.urlopen(
  File "/home/tthau/.local/lib/python3.10/site-packages/urllib3/connectionpool.py", line 843, in urlopen
    retries = retries.increment(
  File "/home/tthau/.local/lib/python3.10/site-packages/urllib3/util/retry.py", line 519, in increment
    raise MaxRetryError(_pool, url, reason) from reason  # type: ignore[arg-type]
urllib3.exceptions.MaxRetryError: HTTPConnectionPool(host='localhost', port=33723): Max retries exceeded with url: /session/5c3037b876a106c9b1369a9069e33b8d/elements (Caused by NewConnectionError('<urllib3.connection.HTTPConnection object at 0x741d735d3d60>: Failed to establish a new connection: [Errno 111] Connection refused'))

During handling of the above exception, another exception occurred:

Traceback (most recent call last):
  File "/home/tthau/.local/lib/python3.10/site-packages/urllib3/connection.py", line 196, in _new_conn
    sock = connection.create_connection(
  File "/home/tthau/.local/lib/python3.10/site-packages/urllib3/util/connection.py", line 85, in create_connection
    raise err
  File "/home/tthau/.local/lib/python3.10/site-packages/urllib3/util/connection.py", line 73, in create_connection
    sock.connect(sa)
ConnectionRefusedError: [Errno 111] Connection refused

The above exception was the direct cause of the following exception:

Traceback (most recent call last):
  File "/home/tthau/.local/lib/python3.10/site-packages/urllib3/connectionpool.py", line 789, in urlopen
    response = self._make_request(
  File "/home/tthau/.local/lib/python3.10/site-packages/urllib3/connectionpool.py", line 495, in _make_request
    conn.request(
  File "/home/tthau/.local/lib/python3.10/site-packages/urllib3/connection.py", line 398, in request
    self.endheaders()
  File "/usr/lib/python3.10/http/client.py", line 1278, in endheaders
    self._send_output(message_body, encode_chunked=encode_chunked)
  File "/usr/lib/python3.10/http/client.py", line 1038, in _send_output
    self.send(msg)
  File "/usr/lib/python3.10/http/client.py", line 976, in send
    self.connect()
  File "/home/tthau/.local/lib/python3.10/site-packages/urllib3/connection.py", line 236, in connect
    self.sock = self._new_conn()
  File "/home/tthau/.local/lib/python3.10/site-packages/urllib3/connection.py", line 211, in _new_conn
    raise NewConnectionError(
urllib3.exceptions.NewConnectionError: <urllib3.connection.HTTPConnection object at 0x741d7344c490>: Failed to establish a new connection: [Errno 111] Connection refused

The above exception was the direct cause of the following exception:

Traceback (most recent call last):
  File "/home/tthau/PROJECT/BKGGPT/clone_album.py", line 410, in <module>
    driver.save_screenshot("password_input_error.png")
  File "/home/tthau/.local/lib/python3.10/site-packages/selenium/webdriver/remote/webdriver.py", line 994, in save_screenshot
    return self.get_screenshot_as_file(filename)
  File "/home/tthau/.local/lib/python3.10/site-packages/selenium/webdriver/remote/webdriver.py", line 969, in get_screenshot_as_file
    png = self.get_screenshot_as_png()
  File "/home/tthau/.local/lib/python3.10/site-packages/selenium/webdriver/remote/webdriver.py", line 1003, in get_screenshot_as_png
    return b64decode(self.get_screenshot_as_base64().encode("ascii"))
  File "/home/tthau/.local/lib/python3.10/site-packages/selenium/webdriver/remote/webdriver.py", line 1013, in get_screenshot_as_base64
    return self.execute(Command.SCREENSHOT)["value"]
  File "/home/tthau/.local/lib/python3.10/site-packages/selenium/webdriver/remote/webdriver.py", line 427, in execute
    response = self.command_executor.execute(driver_command, params)
  File "/home/tthau/.local/lib/python3.10/site-packages/selenium/webdriver/remote/remote_connection.py", line 404, in execute
    return self._request(command_info[0], url, body=data)
  File "/home/tthau/.local/lib/python3.10/site-packages/selenium/webdriver/remote/remote_connection.py", line 428, in _request
    response = self._conn.request(method, url, body=body, headers=headers, timeout=self._client_config.timeout)
  File "/home/tthau/.local/lib/python3.10/site-packages/urllib3/_request_methods.py", line 136, in request
    return self.request_encode_url(
  File "/home/tthau/.local/lib/python3.10/site-packages/urllib3/_request_methods.py", line 183, in request_encode_url
    return self.urlopen(method, url, **extra_kw)
  File "/home/tthau/.local/lib/python3.10/site-packages/urllib3/poolmanager.py", line 443, in urlopen
    response = conn.urlopen(method, u.request_uri, **kw)
  File "/home/tthau/.local/lib/python3.10/site-packages/urllib3/connectionpool.py", line 873, in urlopen
    return self.urlopen(
  File "/home/tthau/.local/lib/python3.10/site-packages/urllib3/connectionpool.py", line 873, in urlopen
    return self.urlopen(
  File "/home/tthau/.local/lib/python3.10/site-packages/urllib3/connectionpool.py", line 873, in urlopen
    return self.urlopen(
  File "/home/tthau/.local/lib/python3.10/site-packages/urllib3/connectionpool.py", line 843, in urlopen
    retries = retries.increment(
  File "/home/tthau/.local/lib/python3.10/site-packages/urllib3/util/retry.py", line 519, in increment
    raise MaxRetryError(_pool, url, reason) from reason  # type: ignore[arg-type]
urllib3.exceptions.MaxRetryError: HTTPConnectionPool(host='localhost', port=33723): Max retries exceeded with url: /session/5c3037b876a106c9b1369a9069e33b8d/screenshot (Caused by NewConnectionError('<urllib3.connection.HTTPConnection object at 0x741d7344c490>: Failed to establish a new connection: [Errno 111] Connection refused'))

2025-04-04 09:38:14,341 - WARNING - Retrying (Retry(total=2, connect=None, read=None, redirect=None, status=None)) after connection broken by 'NewConnectionError('<urllib3.connection.HTTPConnection object at 0x741d7344c910>: Failed to establish a new connection: [Errno 111] Connection refused')': /session/5c3037b876a106c9b1369a9069e33b8d/screenshot
2025-04-04 09:38:14,342 - WARNING - Retrying (Retry(total=1, connect=None, read=None, redirect=None, status=None)) after connection broken by 'NewConnectionError('<urllib3.connection.HTTPConnection object at 0x741d7344c970>: Failed to establish a new connection: [Errno 111] Connection refused')': /session/5c3037b876a106c9b1369a9069e33b8d/screenshot
2025-04-04 09:38:14,344 - WARNING - Retrying (Retry(total=0, connect=None, read=None, redirect=None, status=None)) after connection broken by 'NewConnectionError('<urllib3.connection.HTTPConnection object at 0x741d7344cbe0>: Failed to establish a new connection: [Errno 111] Connection refused')': /session/5c3037b876a106c9b1369a9069e33b8d/screenshot
2025-04-04 09:38:14,345 - WARNING - Retrying (Retry(total=2, connect=None, read=None, redirect=None, status=None)) after connection broken by 'NewConnectionError('<urllib3.connection.HTTPConnection object at 0x741d735d2e90>: Failed to establish a new connection: [Errno 111] Connection refused')': /session/5c3037b876a106c9b1369a9069e33b8d
2025-04-04 09:38:14,345 - WARNING - Retrying (Retry(total=1, connect=None, read=None, redirect=None, status=None)) after connection broken by 'NewConnectionError('<urllib3.connection.HTTPConnection object at 0x741d7344cca0>: Failed to establish a new connection: [Errno 111] Connection refused')': /session/5c3037b876a106c9b1369a9069e33b8d
2025-04-04 09:38:14,346 - WARNING - Retrying (Retry(total=0, connect=None, read=None, redirect=None, status=None)) after connection broken by 'NewConnectionError('<urllib3.connection.HTTPConnection object at 0x741d7344ce20>: Failed to establish a new connection: [Errno 111] Connection refused')': /session/5c3037b876a106c9b1369a9069e33b8d
2025-04-04 09:38:14,348 - INFO - Đã đóng WebDriver
2025-04-04 09:38:26,231 - INFO - Đang khởi tạo WebDriver...
2025-04-04 09:38:26,231 - INFO - ====== WebDriver manager ======
2025-04-04 09:38:26,324 - INFO - Get LATEST chromedriver version for google-chrome
2025-04-04 09:38:26,340 - INFO - Get LATEST chromedriver version for google-chrome
2025-04-04 09:38:26,354 - INFO - Driver [/home/tthau/.wdm/drivers/chromedriver/linux64/135.0.7049.42/chromedriver-linux64/chromedriver] found in cache
2025-04-04 09:38:28,063 - INFO - Đang đăng nhập vào Google...
2025-04-04 09:38:28,575 - WARNING - Retrying (Retry(total=2, connect=None, read=None, redirect=None, status=None)) after connection broken by 'ConnectionResetError(104, 'Connection reset by peer')': /session/6a7531871f2ec28ccc971fe0db5de685
2025-04-04 09:38:28,576 - WARNING - Retrying (Retry(total=1, connect=None, read=None, redirect=None, status=None)) after connection broken by 'NewConnectionError('<urllib3.connection.HTTPConnection object at 0x7fd41ed5ed10>: Failed to establish a new connection: [Errno 111] Connection refused')': /session/6a7531871f2ec28ccc971fe0db5de685
2025-04-04 09:38:28,579 - WARNING - Retrying (Retry(total=0, connect=None, read=None, redirect=None, status=None)) after connection broken by 'NewConnectionError('<urllib3.connection.HTTPConnection object at 0x7fd41ed5ee60>: Failed to establish a new connection: [Errno 111] Connection refused')': /session/6a7531871f2ec28ccc971fe0db5de685
2025-04-04 09:38:28,582 - INFO - Đã đóng WebDriver
2025-04-04 09:38:45,498 - INFO - Đang khởi tạo WebDriver...
2025-04-04 09:38:45,499 - INFO - ====== WebDriver manager ======
2025-04-04 09:38:45,598 - INFO - Get LATEST chromedriver version for google-chrome
2025-04-04 09:38:45,620 - INFO - Get LATEST chromedriver version for google-chrome
2025-04-04 09:38:45,644 - INFO - Driver [/home/tthau/.wdm/drivers/chromedriver/linux64/135.0.7049.42/chromedriver-linux64/chromedriver] found in cache
2025-04-04 09:38:47,462 - INFO - Đang đăng nhập vào Google...
2025-04-04 09:38:53,366 - INFO - Đang tìm trường nhập email...
2025-04-04 09:38:53,385 - INFO - Tìm thấy input email bằng ID
2025-04-04 09:38:55,636 - INFO - Đang nhập email: trunghautran0102travel1@gmail.com
2025-04-04 09:39:04,196 - INFO - Đã tìm thấy nút Next, chuẩn bị click...
2025-04-04 09:39:05,613 - INFO - Đã click nút Next sau khi nhập email
2025-04-04 09:39:10,342 - INFO - Đang chờ màn hình nhập mật khẩu...
2025-04-04 09:39:10,954 - INFO - Tìm thấy input password bằng Name
2025-04-04 09:39:13,441 - INFO - Đang nhập mật khẩu...
2025-04-04 09:39:19,535 - INFO - Đã tìm thấy nút Next sau password, chuẩn bị click...
2025-04-04 09:39:20,094 - ERROR - Lỗi khi tìm hoặc click nút passwordNext: Message: move target out of bounds
  (Session info: chrome=135.0.7049.52)
Stacktrace:
#0 0x580ef9a27e6a <unknown>
#1 0x580ef94d9493 <unknown>
#2 0x580ef957ef3e <unknown>
#3 0x580ef9550752 <unknown>
#4 0x580ef95767b5 <unknown>
#5 0x580ef9550523 <unknown>
#6 0x580ef951cef3 <unknown>
#7 0x580ef951db51 <unknown>
#8 0x580ef99ecd2b <unknown>
#9 0x580ef99f0c01 <unknown>
#10 0x580ef99d4512 <unknown>
#11 0x580ef99f1774 <unknown>
#12 0x580ef99b890f <unknown>
#13 0x580ef9a15fb8 <unknown>
#14 0x580ef9a16196 <unknown>
#15 0x580ef9a26cb6 <unknown>
#16 0x791bc3294ac3 <unknown>

2025-04-04 09:39:20,712 - INFO - Chờ đăng nhập hoàn tất...
2025-04-04 09:39:29,391 - INFO - Ghé thăm trang chủ Google Photos trước khi đi đến album...
2025-04-04 09:39:42,769 - INFO - Đang truy cập album: https://photos.app.goo.gl/13SDgSLQNZvE9dDQA
2025-04-04 09:39:54,943 - ERROR - Lỗi khi truy cập album: Message: move target out of bounds
  (Session info: chrome=135.0.7049.52)
Stacktrace:
#0 0x580ef9a27e6a <unknown>
#1 0x580ef94d9493 <unknown>
#2 0x580ef957ef3e <unknown>
#3 0x580ef9550752 <unknown>
#4 0x580ef95767b5 <unknown>
#5 0x580ef9550523 <unknown>
#6 0x580ef951cef3 <unknown>
#7 0x580ef951db51 <unknown>
#8 0x580ef99ecd2b <unknown>
#9 0x580ef99f0c01 <unknown>
#10 0x580ef99d4512 <unknown>
#11 0x580ef99f1774 <unknown>
#12 0x580ef99b890f <unknown>
#13 0x580ef9a15fb8 <unknown>
#14 0x580ef9a16196 <unknown>
#15 0x580ef9a26cb6 <unknown>
#16 0x791bc3294ac3 <unknown>

2025-04-04 09:39:54,944 - ERROR - Traceback (most recent call last):
  File "/home/tthau/PROJECT/BKGGPT/clone_album.py", line 444, in <module>
    actions.move_by_offset(random.randint(50, 300), random.randint(50, 300)).perform()
  File "/home/tthau/.local/lib/python3.10/site-packages/selenium/webdriver/common/action_chains.py", line 94, in perform
    self.w3c_actions.perform()
  File "/home/tthau/.local/lib/python3.10/site-packages/selenium/webdriver/common/actions/action_builder.py", line 170, in perform
    self.driver.execute(Command.W3C_ACTIONS, enc)
  File "/home/tthau/.local/lib/python3.10/site-packages/selenium/webdriver/remote/webdriver.py", line 429, in execute
    self.error_handler.check_response(response)
  File "/home/tthau/.local/lib/python3.10/site-packages/selenium/webdriver/remote/errorhandler.py", line 232, in check_response
    raise exception_class(message, screen, stacktrace)
selenium.common.exceptions.MoveTargetOutOfBoundsException: Message: move target out of bounds
  (Session info: chrome=135.0.7049.52)
Stacktrace:
#0 0x580ef9a27e6a <unknown>
#1 0x580ef94d9493 <unknown>
#2 0x580ef957ef3e <unknown>
#3 0x580ef9550752 <unknown>
#4 0x580ef95767b5 <unknown>
#5 0x580ef9550523 <unknown>
#6 0x580ef951cef3 <unknown>
#7 0x580ef951db51 <unknown>
#8 0x580ef99ecd2b <unknown>
#9 0x580ef99f0c01 <unknown>
#10 0x580ef99d4512 <unknown>
#11 0x580ef99f1774 <unknown>
#12 0x580ef99b890f <unknown>
#13 0x580ef9a15fb8 <unknown>
#14 0x580ef9a16196 <unknown>
#15 0x580ef9a26cb6 <unknown>
#16 0x791bc3294ac3 <unknown>


2025-04-04 09:39:56,064 - INFO - Hoàn thành thao tác!
2025-04-04 09:39:58,793 - INFO - Đã đóng WebDriver
2025-04-04 10:14:58,823 - INFO - Đang khởi tạo WebDriver...
2025-04-04 10:14:58,823 - INFO - ====== WebDriver manager ======
2025-04-04 10:14:58,933 - INFO - Get LATEST chromedriver version for google-chrome
2025-04-04 10:14:58,949 - INFO - Get LATEST chromedriver version for google-chrome
2025-04-04 10:14:58,968 - INFO - Driver [/home/tthau/.wdm/drivers/chromedriver/linux64/135.0.7049.42/chromedriver-linux64/chromedriver] found in cache
2025-04-04 10:14:59,107 - ERROR - Lỗi không xác định: Message: session not created: probably user data directory is already in use, please specify a unique value for --user-data-dir argument, or don't use --user-data-dir
Stacktrace:
#0 0x6449eb4c3e6a <unknown>
#1 0x6449eaf75640 <unknown>
#2 0x6449eafaf11b <unknown>
#3 0x6449eafaae6f <unknown>
#4 0x6449eaffb0ce <unknown>
#5 0x6449eaffa5f6 <unknown>
#6 0x6449eafec523 <unknown>
#7 0x6449eafb8ef3 <unknown>
#8 0x6449eafb9b51 <unknown>
#9 0x6449eb488d2b <unknown>
#10 0x6449eb48cc01 <unknown>
#11 0x6449eb470512 <unknown>
#12 0x6449eb48d774 <unknown>
#13 0x6449eb45490f <unknown>
#14 0x6449eb4b1fb8 <unknown>
#15 0x6449eb4b2196 <unknown>
#16 0x6449eb4c2cb6 <unknown>
#17 0x7ae0ee894ac3 <unknown>

2025-04-04 10:14:59,108 - ERROR - Traceback (most recent call last):
  File "/home/tthau/PROJECT/BKGGPT/clone_album.py", line 51, in <module>
    driver = webdriver.Chrome(service=Service(ChromeDriverManager().install()), options=chrome_options)
  File "/home/tthau/.local/lib/python3.10/site-packages/selenium/webdriver/chrome/webdriver.py", line 45, in __init__
    super().__init__(
  File "/home/tthau/.local/lib/python3.10/site-packages/selenium/webdriver/chromium/webdriver.py", line 66, in __init__
    super().__init__(command_executor=executor, options=options)
  File "/home/tthau/.local/lib/python3.10/site-packages/selenium/webdriver/remote/webdriver.py", line 250, in __init__
    self.start_session(capabilities)
  File "/home/tthau/.local/lib/python3.10/site-packages/selenium/webdriver/remote/webdriver.py", line 342, in start_session
    response = self.execute(Command.NEW_SESSION, caps)["value"]
  File "/home/tthau/.local/lib/python3.10/site-packages/selenium/webdriver/remote/webdriver.py", line 429, in execute
    self.error_handler.check_response(response)
  File "/home/tthau/.local/lib/python3.10/site-packages/selenium/webdriver/remote/errorhandler.py", line 232, in check_response
    raise exception_class(message, screen, stacktrace)
selenium.common.exceptions.SessionNotCreatedException: Message: session not created: probably user data directory is already in use, please specify a unique value for --user-data-dir argument, or don't use --user-data-dir
Stacktrace:
#0 0x6449eb4c3e6a <unknown>
#1 0x6449eaf75640 <unknown>
#2 0x6449eafaf11b <unknown>
#3 0x6449eafaae6f <unknown>
#4 0x6449eaffb0ce <unknown>
#5 0x6449eaffa5f6 <unknown>
#6 0x6449eafec523 <unknown>
#7 0x6449eafb8ef3 <unknown>
#8 0x6449eafb9b51 <unknown>
#9 0x6449eb488d2b <unknown>
#10 0x6449eb48cc01 <unknown>
#11 0x6449eb470512 <unknown>
#12 0x6449eb48d774 <unknown>
#13 0x6449eb45490f <unknown>
#14 0x6449eb4b1fb8 <unknown>
#15 0x6449eb4b2196 <unknown>
#16 0x6449eb4c2cb6 <unknown>
#17 0x7ae0ee894ac3 <unknown>


2025-04-04 10:16:11,281 - INFO - Đang khởi tạo WebDriver...
2025-04-04 10:16:11,282 - INFO - ====== WebDriver manager ======
2025-04-04 10:16:11,405 - INFO - Get LATEST chromedriver version for google-chrome
2025-04-04 10:16:11,426 - INFO - Get LATEST chromedriver version for google-chrome
2025-04-04 10:16:11,442 - INFO - Driver [/home/tthau/.wdm/drivers/chromedriver/linux64/135.0.7049.42/chromedriver-linux64/chromedriver] found in cache
2025-04-04 10:16:11,673 - ERROR - Lỗi không xác định: Message: session not created: probably user data directory is already in use, please specify a unique value for --user-data-dir argument, or don't use --user-data-dir
Stacktrace:
#0 0x64169601ee6a <unknown>
#1 0x641695ad0640 <unknown>
#2 0x641695b0a11b <unknown>
#3 0x641695b05e6f <unknown>
#4 0x641695b560ce <unknown>
#5 0x641695b555f6 <unknown>
#6 0x641695b47523 <unknown>
#7 0x641695b13ef3 <unknown>
#8 0x641695b14b51 <unknown>
#9 0x641695fe3d2b <unknown>
#10 0x641695fe7c01 <unknown>
#11 0x641695fcb512 <unknown>
#12 0x641695fe8774 <unknown>
#13 0x641695faf90f <unknown>
#14 0x64169600cfb8 <unknown>
#15 0x64169600d196 <unknown>
#16 0x64169601dcb6 <unknown>
#17 0x7fa753494ac3 <unknown>

2025-04-04 10:16:11,674 - ERROR - Traceback (most recent call last):
  File "/home/tthau/PROJECT/BKGGPT/clone_album.py", line 51, in <module>
    driver = webdriver.Chrome(service=Service(ChromeDriverManager().install()), options=chrome_options)
  File "/home/tthau/.local/lib/python3.10/site-packages/selenium/webdriver/chrome/webdriver.py", line 45, in __init__
    super().__init__(
  File "/home/tthau/.local/lib/python3.10/site-packages/selenium/webdriver/chromium/webdriver.py", line 66, in __init__
    super().__init__(command_executor=executor, options=options)
  File "/home/tthau/.local/lib/python3.10/site-packages/selenium/webdriver/remote/webdriver.py", line 250, in __init__
    self.start_session(capabilities)
  File "/home/tthau/.local/lib/python3.10/site-packages/selenium/webdriver/remote/webdriver.py", line 342, in start_session
    response = self.execute(Command.NEW_SESSION, caps)["value"]
  File "/home/tthau/.local/lib/python3.10/site-packages/selenium/webdriver/remote/webdriver.py", line 429, in execute
    self.error_handler.check_response(response)
  File "/home/tthau/.local/lib/python3.10/site-packages/selenium/webdriver/remote/errorhandler.py", line 232, in check_response
    raise exception_class(message, screen, stacktrace)
selenium.common.exceptions.SessionNotCreatedException: Message: session not created: probably user data directory is already in use, please specify a unique value for --user-data-dir argument, or don't use --user-data-dir
Stacktrace:
#0 0x64169601ee6a <unknown>
#1 0x641695ad0640 <unknown>
#2 0x641695b0a11b <unknown>
#3 0x641695b05e6f <unknown>
#4 0x641695b560ce <unknown>
#5 0x641695b555f6 <unknown>
#6 0x641695b47523 <unknown>
#7 0x641695b13ef3 <unknown>
#8 0x641695b14b51 <unknown>
#9 0x641695fe3d2b <unknown>
#10 0x641695fe7c01 <unknown>
#11 0x641695fcb512 <unknown>
#12 0x641695fe8774 <unknown>
#13 0x641695faf90f <unknown>
#14 0x64169600cfb8 <unknown>
#15 0x64169600d196 <unknown>
#16 0x64169601dcb6 <unknown>
#17 0x7fa753494ac3 <unknown>


2025-04-04 14:53:50,485 - INFO - Đang khởi tạo WebDriver...
2025-04-04 14:53:50,485 - INFO - ====== WebDriver manager ======
2025-04-04 14:53:50,576 - INFO - Get LATEST chromedriver version for google-chrome
2025-04-04 14:53:50,606 - INFO - Get LATEST chromedriver version for google-chrome
2025-04-04 14:53:50,626 - INFO - Driver [/home/tthau/.wdm/drivers/chromedriver/linux64/135.0.7049.42/chromedriver-linux64/chromedriver] found in cache
2025-04-04 14:53:52,265 - INFO - Đang đăng nhập vào Google...
2025-04-04 14:53:57,950 - INFO - Đang tìm trường nhập email...
2025-04-04 14:53:57,964 - INFO - Tìm thấy input email bằng ID
2025-04-04 14:54:00,075 - INFO - Đang nhập email: trunghautran0102travel1@gmail.com
2025-04-04 14:54:09,279 - ERROR - Lỗi khi nhập email: Message: move target out of bounds
  (Session info: chrome=135.0.7049.52)
Stacktrace:
#0 0x5939a76c0e6a <unknown>
#1 0x5939a7172493 <unknown>
#2 0x5939a7217f3e <unknown>
#3 0x5939a71e9752 <unknown>
#4 0x5939a720f7b5 <unknown>
#5 0x5939a71e9523 <unknown>
#6 0x5939a71b5ef3 <unknown>
#7 0x5939a71b6b51 <unknown>
#8 0x5939a7685d2b <unknown>
#9 0x5939a7689c01 <unknown>
#10 0x5939a766d512 <unknown>
#11 0x5939a768a774 <unknown>
#12 0x5939a765190f <unknown>
#13 0x5939a76aefb8 <unknown>
#14 0x5939a76af196 <unknown>
#15 0x5939a76bfcb6 <unknown>
#16 0x7d112fc94ac3 <unknown>

2025-04-04 14:54:13,048 - INFO - Đang chờ màn hình nhập mật khẩu...
2025-04-04 14:54:43,987 - INFO - Không tìm thấy input password bằng Name, thử cách khác...
2025-04-04 14:54:44,003 - INFO - Tìm thấy input password bằng XPath type
2025-04-04 14:54:45,401 - ERROR - Lỗi khi nhập mật khẩu: Message: element not interactable: [object HTMLInputElement] has no size and location
  (Session info: chrome=135.0.7049.52)
Stacktrace:
#0 0x5939a76c0e6a <unknown>
#1 0x5939a7172640 <unknown>
#2 0x5939a7179246 <unknown>
#3 0x5939a717bab8 <unknown>
#4 0x5939a717bb43 <unknown>
#5 0x5939a71c9eac <unknown>
#6 0x5939a71c9262 <unknown>
#7 0x5939a7217cad <unknown>
#8 0x5939a71e9752 <unknown>
#9 0x5939a720f7b5 <unknown>
#10 0x5939a71e9523 <unknown>
#11 0x5939a71b5ef3 <unknown>
#12 0x5939a71b6b51 <unknown>
#13 0x5939a7685d2b <unknown>
#14 0x5939a7689c01 <unknown>
#15 0x5939a766d512 <unknown>
#16 0x5939a768a774 <unknown>
#17 0x5939a765190f <unknown>
#18 0x5939a76aefb8 <unknown>
#19 0x5939a76af196 <unknown>
#20 0x5939a76bfcb6 <unknown>
#21 0x7d112fc94ac3 <unknown>

2025-04-04 14:54:46,061 - INFO - Chờ đăng nhập hoàn tất...
2025-04-04 14:54:53,892 - INFO - Ghé thăm trang chủ Google Photos trước khi đi đến album...
2025-04-04 14:55:07,819 - INFO - Đang truy cập album: https://photos.app.goo.gl/13SDgSLQNZvE9dDQA
2025-04-04 14:55:21,156 - INFO - Đã chụp ảnh màn hình trang album
2025-04-04 14:55:24,066 - INFO - Tìm nút 'Lưu ảnh'...
2025-04-04 14:55:24,081 - INFO - Tìm thấy 7 buttons trên trang album
2025-04-04 14:55:24,125 - INFO - Button #0: text='', aria-label='Add photos'
2025-04-04 14:55:24,153 - INFO - Button #1: text='', aria-label='View activity'
2025-04-04 14:55:24,218 - INFO - Button #2: text='', aria-label='Save photos'
2025-04-04 14:55:24,246 - INFO - Button #3: text='', aria-label='Share'
2025-04-04 14:55:24,277 - INFO - Button #4: text='', aria-label='More options'
2025-04-04 14:55:24,319 - INFO - Button #6: text='', aria-label='Like'
2025-04-04 14:55:24,677 - ERROR - Không tìm thấy nút 'Lưu ảnh'
2025-04-04 14:55:26,423 - WARNING - Retrying (Retry(total=2, connect=None, read=None, redirect=None, status=None)) after connection broken by 'ConnectionResetError(104, 'Connection reset by peer')': /session/b1fa971e323fa8b25a584b43fa7a4997
2025-04-04 14:55:26,424 - WARNING - Retrying (Retry(total=1, connect=None, read=None, redirect=None, status=None)) after connection broken by 'NewConnectionError('<urllib3.connection.HTTPConnection object at 0x7f218d663280>: Failed to establish a new connection: [Errno 111] Connection refused')': /session/b1fa971e323fa8b25a584b43fa7a4997
2025-04-04 14:55:26,426 - WARNING - Retrying (Retry(total=0, connect=None, read=None, redirect=None, status=None)) after connection broken by 'NewConnectionError('<urllib3.connection.HTTPConnection object at 0x7f218d6629b0>: Failed to establish a new connection: [Errno 111] Connection refused')': /session/b1fa971e323fa8b25a584b43fa7a4997
2025-04-04 14:55:26,430 - INFO - Đã đóng WebDriver
2025-04-04 14:55:29,256 - INFO - Đang khởi tạo WebDriver...
2025-04-04 14:55:29,257 - INFO - ====== WebDriver manager ======
2025-04-04 14:55:29,375 - INFO - Get LATEST chromedriver version for google-chrome
2025-04-04 14:55:29,396 - INFO - Get LATEST chromedriver version for google-chrome
2025-04-04 14:55:29,416 - INFO - Driver [/home/tthau/.wdm/drivers/chromedriver/linux64/135.0.7049.42/chromedriver-linux64/chromedriver] found in cache
2025-04-04 14:55:31,310 - INFO - Đang đăng nhập vào Google...
2025-04-04 14:55:36,535 - INFO - Đang tìm trường nhập email...
2025-04-04 14:55:36,549 - INFO - Tìm thấy input email bằng ID
2025-04-04 14:55:38,676 - INFO - Đang nhập email: trunghautran0102travel1@gmail.com
2025-04-04 14:55:46,466 - ERROR - Lỗi khi nhập email: Message: move target out of bounds
  (Session info: chrome=135.0.7049.52)
Stacktrace:
#0 0x601f24c4be6a <unknown>
#1 0x601f246fd493 <unknown>
#2 0x601f247a2f3e <unknown>
#3 0x601f24774752 <unknown>
#4 0x601f2479a7b5 <unknown>
#5 0x601f24774523 <unknown>
#6 0x601f24740ef3 <unknown>
#7 0x601f24741b51 <unknown>
#8 0x601f24c10d2b <unknown>
#9 0x601f24c14c01 <unknown>
#10 0x601f24bf8512 <unknown>
#11 0x601f24c15774 <unknown>
#12 0x601f24bdc90f <unknown>
#13 0x601f24c39fb8 <unknown>
#14 0x601f24c3a196 <unknown>
#15 0x601f24c4acb6 <unknown>
#16 0x71cceaa94ac3 <unknown>

2025-04-04 14:55:51,393 - INFO - Đang chờ màn hình nhập mật khẩu...
2025-04-04 14:55:53,961 - INFO - Không tìm thấy input password bằng Name, thử cách khác...
2025-04-04 14:55:53,963 - INFO - Không tìm thấy input password bằng XPath type
2025-04-04 14:55:53,964 - WARNING - Retrying (Retry(total=2, connect=None, read=None, redirect=None, status=None)) after connection broken by 'NewConnectionError('<urllib3.connection.HTTPConnection object at 0x749b3f463340>: Failed to establish a new connection: [Errno 111] Connection refused')': /session/43718555b2bc3eda2ca9e5ca153d48b2/element
2025-04-04 14:55:53,964 - WARNING - Retrying (Retry(total=1, connect=None, read=None, redirect=None, status=None)) after connection broken by 'NewConnectionError('<urllib3.connection.HTTPConnection object at 0x749b3f463280>: Failed to establish a new connection: [Errno 111] Connection refused')': /session/43718555b2bc3eda2ca9e5ca153d48b2/element
2025-04-04 14:55:53,965 - WARNING - Retrying (Retry(total=0, connect=None, read=None, redirect=None, status=None)) after connection broken by 'NewConnectionError('<urllib3.connection.HTTPConnection object at 0x749b3f4634c0>: Failed to establish a new connection: [Errno 111] Connection refused')': /session/43718555b2bc3eda2ca9e5ca153d48b2/element
2025-04-04 14:55:53,966 - INFO - Không tìm thấy input password bằng aria-label
2025-04-04 14:55:53,967 - WARNING - Retrying (Retry(total=2, connect=None, read=None, redirect=None, status=None)) after connection broken by 'NewConnectionError('<urllib3.connection.HTTPConnection object at 0x749b3f463700>: Failed to establish a new connection: [Errno 111] Connection refused')': /session/43718555b2bc3eda2ca9e5ca153d48b2/elements
2025-04-04 14:55:53,968 - WARNING - Retrying (Retry(total=1, connect=None, read=None, redirect=None, status=None)) after connection broken by 'NewConnectionError('<urllib3.connection.HTTPConnection object at 0x749b3f4638e0>: Failed to establish a new connection: [Errno 111] Connection refused')': /session/43718555b2bc3eda2ca9e5ca153d48b2/elements
2025-04-04 14:55:53,968 - WARNING - Retrying (Retry(total=0, connect=None, read=None, redirect=None, status=None)) after connection broken by 'NewConnectionError('<urllib3.connection.HTTPConnection object at 0x749b3f463af0>: Failed to establish a new connection: [Errno 111] Connection refused')': /session/43718555b2bc3eda2ca9e5ca153d48b2/elements
2025-04-04 14:55:53,969 - ERROR - Lỗi khi nhập mật khẩu: HTTPConnectionPool(host='localhost', port=52955): Max retries exceeded with url: /session/43718555b2bc3eda2ca9e5ca153d48b2/elements (Caused by NewConnectionError('<urllib3.connection.HTTPConnection object at 0x749b3f463d00>: Failed to establish a new connection: [Errno 111] Connection refused'))
2025-04-04 14:55:53,970 - WARNING - Retrying (Retry(total=2, connect=None, read=None, redirect=None, status=None)) after connection broken by 'NewConnectionError('<urllib3.connection.HTTPConnection object at 0x749b3f463f70>: Failed to establish a new connection: [Errno 111] Connection refused')': /session/43718555b2bc3eda2ca9e5ca153d48b2/screenshot
2025-04-04 14:55:53,970 - WARNING - Retrying (Retry(total=1, connect=None, read=None, redirect=None, status=None)) after connection broken by 'NewConnectionError('<urllib3.connection.HTTPConnection object at 0x749b3f2dc130>: Failed to establish a new connection: [Errno 111] Connection refused')': /session/43718555b2bc3eda2ca9e5ca153d48b2/screenshot
2025-04-04 14:55:53,971 - WARNING - Retrying (Retry(total=0, connect=None, read=None, redirect=None, status=None)) after connection broken by 'NewConnectionError('<urllib3.connection.HTTPConnection object at 0x749b3f2dc2b0>: Failed to establish a new connection: [Errno 111] Connection refused')': /session/43718555b2bc3eda2ca9e5ca153d48b2/screenshot
2025-04-04 14:55:53,972 - ERROR - Lỗi không xác định: HTTPConnectionPool(host='localhost', port=52955): Max retries exceeded with url: /session/43718555b2bc3eda2ca9e5ca153d48b2/screenshot (Caused by NewConnectionError('<urllib3.connection.HTTPConnection object at 0x749b3f2dc430>: Failed to establish a new connection: [Errno 111] Connection refused'))
2025-04-04 14:55:53,975 - ERROR - Traceback (most recent call last):
  File "/home/tthau/.local/lib/python3.10/site-packages/urllib3/connection.py", line 196, in _new_conn
    sock = connection.create_connection(
  File "/home/tthau/.local/lib/python3.10/site-packages/urllib3/util/connection.py", line 85, in create_connection
    raise err
  File "/home/tthau/.local/lib/python3.10/site-packages/urllib3/util/connection.py", line 73, in create_connection
    sock.connect(sa)
ConnectionRefusedError: [Errno 111] Connection refused

The above exception was the direct cause of the following exception:

Traceback (most recent call last):
  File "/home/tthau/.local/lib/python3.10/site-packages/urllib3/connectionpool.py", line 789, in urlopen
    response = self._make_request(
  File "/home/tthau/.local/lib/python3.10/site-packages/urllib3/connectionpool.py", line 495, in _make_request
    conn.request(
  File "/home/tthau/.local/lib/python3.10/site-packages/urllib3/connection.py", line 398, in request
    self.endheaders()
  File "/usr/lib/python3.10/http/client.py", line 1278, in endheaders
    self._send_output(message_body, encode_chunked=encode_chunked)
  File "/usr/lib/python3.10/http/client.py", line 1038, in _send_output
    self.send(msg)
  File "/usr/lib/python3.10/http/client.py", line 976, in send
    self.connect()
  File "/home/tthau/.local/lib/python3.10/site-packages/urllib3/connection.py", line 236, in connect
    self.sock = self._new_conn()
  File "/home/tthau/.local/lib/python3.10/site-packages/urllib3/connection.py", line 211, in _new_conn
    raise NewConnectionError(
urllib3.exceptions.NewConnectionError: <urllib3.connection.HTTPConnection object at 0x749b3f463d00>: Failed to establish a new connection: [Errno 111] Connection refused

The above exception was the direct cause of the following exception:

Traceback (most recent call last):
  File "/home/tthau/PROJECT/BKGGPT/clone_album.py", line 334, in <module>
    all_inputs = driver.find_elements(By.TAG_NAME, "input")
  File "/home/tthau/.local/lib/python3.10/site-packages/selenium/webdriver/remote/webdriver.py", line 936, in find_elements
    return self.execute(Command.FIND_ELEMENTS, {"using": by, "value": value})["value"] or []
  File "/home/tthau/.local/lib/python3.10/site-packages/selenium/webdriver/remote/webdriver.py", line 427, in execute
    response = self.command_executor.execute(driver_command, params)
  File "/home/tthau/.local/lib/python3.10/site-packages/selenium/webdriver/remote/remote_connection.py", line 404, in execute
    return self._request(command_info[0], url, body=data)
  File "/home/tthau/.local/lib/python3.10/site-packages/selenium/webdriver/remote/remote_connection.py", line 428, in _request
    response = self._conn.request(method, url, body=body, headers=headers, timeout=self._client_config.timeout)
  File "/home/tthau/.local/lib/python3.10/site-packages/urllib3/_request_methods.py", line 144, in request
    return self.request_encode_body(
  File "/home/tthau/.local/lib/python3.10/site-packages/urllib3/_request_methods.py", line 279, in request_encode_body
    return self.urlopen(method, url, **extra_kw)
  File "/home/tthau/.local/lib/python3.10/site-packages/urllib3/poolmanager.py", line 443, in urlopen
    response = conn.urlopen(method, u.request_uri, **kw)
  File "/home/tthau/.local/lib/python3.10/site-packages/urllib3/connectionpool.py", line 873, in urlopen
    return self.urlopen(
  File "/home/tthau/.local/lib/python3.10/site-packages/urllib3/connectionpool.py", line 873, in urlopen
    return self.urlopen(
  File "/home/tthau/.local/lib/python3.10/site-packages/urllib3/connectionpool.py", line 873, in urlopen
    return self.urlopen(
  File "/home/tthau/.local/lib/python3.10/site-packages/urllib3/connectionpool.py", line 843, in urlopen
    retries = retries.increment(
  File "/home/tthau/.local/lib/python3.10/site-packages/urllib3/util/retry.py", line 519, in increment
    raise MaxRetryError(_pool, url, reason) from reason  # type: ignore[arg-type]
urllib3.exceptions.MaxRetryError: HTTPConnectionPool(host='localhost', port=52955): Max retries exceeded with url: /session/43718555b2bc3eda2ca9e5ca153d48b2/elements (Caused by NewConnectionError('<urllib3.connection.HTTPConnection object at 0x749b3f463d00>: Failed to establish a new connection: [Errno 111] Connection refused'))

During handling of the above exception, another exception occurred:

Traceback (most recent call last):
  File "/home/tthau/.local/lib/python3.10/site-packages/urllib3/connection.py", line 196, in _new_conn
    sock = connection.create_connection(
  File "/home/tthau/.local/lib/python3.10/site-packages/urllib3/util/connection.py", line 85, in create_connection
    raise err
  File "/home/tthau/.local/lib/python3.10/site-packages/urllib3/util/connection.py", line 73, in create_connection
    sock.connect(sa)
ConnectionRefusedError: [Errno 111] Connection refused

The above exception was the direct cause of the following exception:

Traceback (most recent call last):
  File "/home/tthau/.local/lib/python3.10/site-packages/urllib3/connectionpool.py", line 789, in urlopen
    response = self._make_request(
  File "/home/tthau/.local/lib/python3.10/site-packages/urllib3/connectionpool.py", line 495, in _make_request
    conn.request(
  File "/home/tthau/.local/lib/python3.10/site-packages/urllib3/connection.py", line 398, in request
    self.endheaders()
  File "/usr/lib/python3.10/http/client.py", line 1278, in endheaders
    self._send_output(message_body, encode_chunked=encode_chunked)
  File "/usr/lib/python3.10/http/client.py", line 1038, in _send_output
    self.send(msg)
  File "/usr/lib/python3.10/http/client.py", line 976, in send
    self.connect()
  File "/home/tthau/.local/lib/python3.10/site-packages/urllib3/connection.py", line 236, in connect
    self.sock = self._new_conn()
  File "/home/tthau/.local/lib/python3.10/site-packages/urllib3/connection.py", line 211, in _new_conn
    raise NewConnectionError(
urllib3.exceptions.NewConnectionError: <urllib3.connection.HTTPConnection object at 0x749b3f2dc430>: Failed to establish a new connection: [Errno 111] Connection refused

The above exception was the direct cause of the following exception:

Traceback (most recent call last):
  File "/home/tthau/PROJECT/BKGGPT/clone_album.py", line 410, in <module>
    driver.save_screenshot("password_input_error.png")
  File "/home/tthau/.local/lib/python3.10/site-packages/selenium/webdriver/remote/webdriver.py", line 994, in save_screenshot
    return self.get_screenshot_as_file(filename)
  File "/home/tthau/.local/lib/python3.10/site-packages/selenium/webdriver/remote/webdriver.py", line 969, in get_screenshot_as_file
    png = self.get_screenshot_as_png()
  File "/home/tthau/.local/lib/python3.10/site-packages/selenium/webdriver/remote/webdriver.py", line 1003, in get_screenshot_as_png
    return b64decode(self.get_screenshot_as_base64().encode("ascii"))
  File "/home/tthau/.local/lib/python3.10/site-packages/selenium/webdriver/remote/webdriver.py", line 1013, in get_screenshot_as_base64
    return self.execute(Command.SCREENSHOT)["value"]
  File "/home/tthau/.local/lib/python3.10/site-packages/selenium/webdriver/remote/webdriver.py", line 427, in execute
    response = self.command_executor.execute(driver_command, params)
  File "/home/tthau/.local/lib/python3.10/site-packages/selenium/webdriver/remote/remote_connection.py", line 404, in execute
    return self._request(command_info[0], url, body=data)
  File "/home/tthau/.local/lib/python3.10/site-packages/selenium/webdriver/remote/remote_connection.py", line 428, in _request
    response = self._conn.request(method, url, body=body, headers=headers, timeout=self._client_config.timeout)
  File "/home/tthau/.local/lib/python3.10/site-packages/urllib3/_request_methods.py", line 136, in request
    return self.request_encode_url(
  File "/home/tthau/.local/lib/python3.10/site-packages/urllib3/_request_methods.py", line 183, in request_encode_url
    return self.urlopen(method, url, **extra_kw)
  File "/home/tthau/.local/lib/python3.10/site-packages/urllib3/poolmanager.py", line 443, in urlopen
    response = conn.urlopen(method, u.request_uri, **kw)
  File "/home/tthau/.local/lib/python3.10/site-packages/urllib3/connectionpool.py", line 873, in urlopen
    return self.urlopen(
  File "/home/tthau/.local/lib/python3.10/site-packages/urllib3/connectionpool.py", line 873, in urlopen
    return self.urlopen(
  File "/home/tthau/.local/lib/python3.10/site-packages/urllib3/connectionpool.py", line 873, in urlopen
    return self.urlopen(
  File "/home/tthau/.local/lib/python3.10/site-packages/urllib3/connectionpool.py", line 843, in urlopen
    retries = retries.increment(
  File "/home/tthau/.local/lib/python3.10/site-packages/urllib3/util/retry.py", line 519, in increment
    raise MaxRetryError(_pool, url, reason) from reason  # type: ignore[arg-type]
urllib3.exceptions.MaxRetryError: HTTPConnectionPool(host='localhost', port=52955): Max retries exceeded with url: /session/43718555b2bc3eda2ca9e5ca153d48b2/screenshot (Caused by NewConnectionError('<urllib3.connection.HTTPConnection object at 0x749b3f2dc430>: Failed to establish a new connection: [Errno 111] Connection refused'))

2025-04-04 14:55:53,978 - WARNING - Retrying (Retry(total=2, connect=None, read=None, redirect=None, status=None)) after connection broken by 'NewConnectionError('<urllib3.connection.HTTPConnection object at 0x749b3f2dc8b0>: Failed to establish a new connection: [Errno 111] Connection refused')': /session/43718555b2bc3eda2ca9e5ca153d48b2/screenshot
2025-04-04 14:55:53,979 - WARNING - Retrying (Retry(total=1, connect=None, read=None, redirect=None, status=None)) after connection broken by 'NewConnectionError('<urllib3.connection.HTTPConnection object at 0x749b3f2dc910>: Failed to establish a new connection: [Errno 111] Connection refused')': /session/43718555b2bc3eda2ca9e5ca153d48b2/screenshot
2025-04-04 14:55:53,980 - WARNING - Retrying (Retry(total=0, connect=None, read=None, redirect=None, status=None)) after connection broken by 'NewConnectionError('<urllib3.connection.HTTPConnection object at 0x749b3f2dcb80>: Failed to establish a new connection: [Errno 111] Connection refused')': /session/43718555b2bc3eda2ca9e5ca153d48b2/screenshot
2025-04-04 14:55:53,983 - WARNING - Retrying (Retry(total=2, connect=None, read=None, redirect=None, status=None)) after connection broken by 'NewConnectionError('<urllib3.connection.HTTPConnection object at 0x749b3f462e90>: Failed to establish a new connection: [Errno 111] Connection refused')': /session/43718555b2bc3eda2ca9e5ca153d48b2
2025-04-04 14:55:53,985 - WARNING - Retrying (Retry(total=1, connect=None, read=None, redirect=None, status=None)) after connection broken by 'NewConnectionError('<urllib3.connection.HTTPConnection object at 0x749b3f4634c0>: Failed to establish a new connection: [Errno 111] Connection refused')': /session/43718555b2bc3eda2ca9e5ca153d48b2
2025-04-04 14:55:53,988 - WARNING - Retrying (Retry(total=0, connect=None, read=None, redirect=None, status=None)) after connection broken by 'NewConnectionError('<urllib3.connection.HTTPConnection object at 0x749b3f2dcdc0>: Failed to establish a new connection: [Errno 111] Connection refused')': /session/43718555b2bc3eda2ca9e5ca153d48b2
2025-04-04 14:55:53,993 - INFO - Đã đóng WebDriver
2025-04-04 16:00:46,371 - INFO - Đang khởi tạo WebDriver...
2025-04-04 16:00:46,373 - INFO - ====== WebDriver manager ======
2025-04-04 16:00:46,480 - INFO - Get LATEST chromedriver version for google-chrome
2025-04-04 16:00:46,501 - INFO - Get LATEST chromedriver version for google-chrome
2025-04-04 16:00:46,520 - INFO - Driver [/home/tthau/.wdm/drivers/chromedriver/linux64/135.0.7049.42/chromedriver-linux64/chromedriver] found in cache
2025-04-04 16:00:48,187 - INFO - Đang đăng nhập vào Google...
2025-04-04 16:00:53,331 - INFO - Đang tìm trường nhập email...
2025-04-04 16:00:53,361 - INFO - Tìm thấy input email bằng ID
2025-04-04 16:00:55,888 - INFO - Đang nhập email: trunghautran0102travel1@gmail.com
2025-04-04 16:01:06,176 - INFO - Đã tìm thấy nút Next, chuẩn bị click...
2025-04-04 16:01:07,509 - INFO - Đã click nút Next sau khi nhập email
2025-04-04 16:01:11,362 - INFO - Đang chờ màn hình nhập mật khẩu...
2025-04-04 16:01:12,098 - INFO - Tìm thấy input password bằng Name
2025-04-04 16:01:13,936 - INFO - Đang nhập mật khẩu...
2025-04-04 16:01:19,664 - INFO - Đã tìm thấy nút Next sau password, chuẩn bị click...
2025-04-04 16:01:20,100 - ERROR - Lỗi khi tìm hoặc click nút passwordNext: Message: move target out of bounds
  (Session info: chrome=135.0.7049.52)
Stacktrace:
#0 0x63015a2fbe6a <unknown>
#1 0x630159dad493 <unknown>
#2 0x630159e52f3e <unknown>
#3 0x630159e24752 <unknown>
#4 0x630159e4a7b5 <unknown>
#5 0x630159e24523 <unknown>
#6 0x630159df0ef3 <unknown>
#7 0x630159df1b51 <unknown>
#8 0x63015a2c0d2b <unknown>
#9 0x63015a2c4c01 <unknown>
#10 0x63015a2a8512 <unknown>
#11 0x63015a2c5774 <unknown>
#12 0x63015a28c90f <unknown>
#13 0x63015a2e9fb8 <unknown>
#14 0x63015a2ea196 <unknown>
#15 0x63015a2facb6 <unknown>
#16 0x75c8a7094ac3 <unknown>

2025-04-04 16:01:20,871 - INFO - Chờ đăng nhập hoàn tất...
2025-04-04 16:01:30,638 - INFO - Ghé thăm trang chủ Google Photos trước khi đi đến album...
2025-04-04 16:01:43,273 - INFO - Đang truy cập album: https://photos.app.goo.gl/13SDgSLQNZvE9dDQA
2025-04-04 16:01:57,660 - INFO - Đã chụp ảnh màn hình trang album
2025-04-04 16:01:59,404 - WARNING - Retrying (Retry(total=2, connect=None, read=None, redirect=None, status=None)) after connection broken by 'ConnectionResetError(104, 'Connection reset by peer')': /session/d6e8c3968daa1e51c7645ea8ceb7dcc1
2025-04-04 16:01:59,405 - WARNING - Retrying (Retry(total=1, connect=None, read=None, redirect=None, status=None)) after connection broken by 'NewConnectionError('<urllib3.connection.HTTPConnection object at 0x772dded9b460>: Failed to establish a new connection: [Errno 111] Connection refused')': /session/d6e8c3968daa1e51c7645ea8ceb7dcc1
2025-04-04 16:01:59,406 - WARNING - Retrying (Retry(total=0, connect=None, read=None, redirect=None, status=None)) after connection broken by 'NewConnectionError('<urllib3.connection.HTTPConnection object at 0x772dded9aad0>: Failed to establish a new connection: [Errno 111] Connection refused')': /session/d6e8c3968daa1e51c7645ea8ceb7dcc1
2025-04-04 16:01:59,410 - INFO - Đã đóng WebDriver
2025-04-04 16:02:02,241 - INFO - Đang khởi tạo WebDriver...
2025-04-04 16:02:02,242 - INFO - ====== WebDriver manager ======
2025-04-04 16:02:02,408 - INFO - Get LATEST chromedriver version for google-chrome
2025-04-04 16:02:02,430 - INFO - Get LATEST chromedriver version for google-chrome
2025-04-04 16:02:02,455 - INFO - Driver [/home/tthau/.wdm/drivers/chromedriver/linux64/135.0.7049.42/chromedriver-linux64/chromedriver] found in cache
2025-04-04 16:02:04,940 - INFO - Đang đăng nhập vào Google...
2025-04-04 16:02:10,658 - INFO - Đang tìm trường nhập email...
2025-04-04 16:02:10,684 - INFO - Tìm thấy input email bằng ID
2025-04-04 16:02:12,846 - INFO - Đang nhập email: trunghautran0102travel1@gmail.com
2025-04-04 16:02:21,909 - ERROR - Lỗi khi nhập email: Message: move target out of bounds
  (Session info: chrome=135.0.7049.52)
Stacktrace:
#0 0x654964943e6a <unknown>
#1 0x6549643f5493 <unknown>
#2 0x65496449af3e <unknown>
#3 0x65496446c752 <unknown>
#4 0x6549644927b5 <unknown>
#5 0x65496446c523 <unknown>
#6 0x654964438ef3 <unknown>
#7 0x654964439b51 <unknown>
#8 0x654964908d2b <unknown>
#9 0x65496490cc01 <unknown>
#10 0x6549648f0512 <unknown>
#11 0x65496490d774 <unknown>
#12 0x6549648d490f <unknown>
#13 0x654964931fb8 <unknown>
#14 0x654964932196 <unknown>
#15 0x654964942cb6 <unknown>
#16 0x75e64a694ac3 <unknown>

2025-04-04 16:02:26,873 - INFO - Đang chờ màn hình nhập mật khẩu...
2025-04-04 16:02:51,369 - INFO - Không tìm thấy input password bằng Name, thử cách khác...
2025-04-04 16:02:51,371 - INFO - Không tìm thấy input password bằng XPath type
2025-04-04 16:02:51,374 - WARNING - Retrying (Retry(total=2, connect=None, read=None, redirect=None, status=None)) after connection broken by 'NewConnectionError('<urllib3.connection.HTTPConnection object at 0x7e37fa2fed40>: Failed to establish a new connection: [Errno 111] Connection refused')': /session/632eb28b7f4e58ec994bd8f5cf420fc0/element
2025-04-04 16:02:51,375 - WARNING - Retrying (Retry(total=1, connect=None, read=None, redirect=None, status=None)) after connection broken by 'NewConnectionError('<urllib3.connection.HTTPConnection object at 0x7e37fa2ff100>: Failed to establish a new connection: [Errno 111] Connection refused')': /session/632eb28b7f4e58ec994bd8f5cf420fc0/element
2025-04-04 16:02:51,382 - WARNING - Retrying (Retry(total=0, connect=None, read=None, redirect=None, status=None)) after connection broken by 'NewConnectionError('<urllib3.connection.HTTPConnection object at 0x7e37fa2ff4c0>: Failed to establish a new connection: [Errno 111] Connection refused')': /session/632eb28b7f4e58ec994bd8f5cf420fc0/element
2025-04-04 16:02:51,391 - INFO - Không tìm thấy input password bằng aria-label
2025-04-04 16:02:51,396 - WARNING - Retrying (Retry(total=2, connect=None, read=None, redirect=None, status=None)) after connection broken by 'NewConnectionError('<urllib3.connection.HTTPConnection object at 0x7e37fa2ff700>: Failed to establish a new connection: [Errno 111] Connection refused')': /session/632eb28b7f4e58ec994bd8f5cf420fc0/elements
2025-04-04 16:02:51,400 - WARNING - Retrying (Retry(total=1, connect=None, read=None, redirect=None, status=None)) after connection broken by 'NewConnectionError('<urllib3.connection.HTTPConnection object at 0x7e37fa2ff8e0>: Failed to establish a new connection: [Errno 111] Connection refused')': /session/632eb28b7f4e58ec994bd8f5cf420fc0/elements
2025-04-04 16:02:51,402 - WARNING - Retrying (Retry(total=0, connect=None, read=None, redirect=None, status=None)) after connection broken by 'NewConnectionError('<urllib3.connection.HTTPConnection object at 0x7e37fa2ffaf0>: Failed to establish a new connection: [Errno 111] Connection refused')': /session/632eb28b7f4e58ec994bd8f5cf420fc0/elements
2025-04-04 16:02:51,404 - ERROR - Lỗi khi nhập mật khẩu: HTTPConnectionPool(host='localhost', port=51409): Max retries exceeded with url: /session/632eb28b7f4e58ec994bd8f5cf420fc0/elements (Caused by NewConnectionError('<urllib3.connection.HTTPConnection object at 0x7e37fa2ffd00>: Failed to establish a new connection: [Errno 111] Connection refused'))
2025-04-04 16:02:51,405 - WARNING - Retrying (Retry(total=2, connect=None, read=None, redirect=None, status=None)) after connection broken by 'NewConnectionError('<urllib3.connection.HTTPConnection object at 0x7e37fa2fff70>: Failed to establish a new connection: [Errno 111] Connection refused')': /session/632eb28b7f4e58ec994bd8f5cf420fc0/screenshot
2025-04-04 16:02:51,408 - WARNING - Retrying (Retry(total=1, connect=None, read=None, redirect=None, status=None)) after connection broken by 'NewConnectionError('<urllib3.connection.HTTPConnection object at 0x7e37fa17c130>: Failed to establish a new connection: [Errno 111] Connection refused')': /session/632eb28b7f4e58ec994bd8f5cf420fc0/screenshot
2025-04-04 16:02:51,409 - WARNING - Retrying (Retry(total=0, connect=None, read=None, redirect=None, status=None)) after connection broken by 'NewConnectionError('<urllib3.connection.HTTPConnection object at 0x7e37fa17c2b0>: Failed to establish a new connection: [Errno 111] Connection refused')': /session/632eb28b7f4e58ec994bd8f5cf420fc0/screenshot
2025-04-04 16:02:51,409 - ERROR - Lỗi không xác định: HTTPConnectionPool(host='localhost', port=51409): Max retries exceeded with url: /session/632eb28b7f4e58ec994bd8f5cf420fc0/screenshot (Caused by NewConnectionError('<urllib3.connection.HTTPConnection object at 0x7e37fa17c430>: Failed to establish a new connection: [Errno 111] Connection refused'))
2025-04-04 16:02:51,412 - ERROR - Traceback (most recent call last):
  File "/home/tthau/.local/lib/python3.10/site-packages/urllib3/connection.py", line 196, in _new_conn
    sock = connection.create_connection(
  File "/home/tthau/.local/lib/python3.10/site-packages/urllib3/util/connection.py", line 85, in create_connection
    raise err
  File "/home/tthau/.local/lib/python3.10/site-packages/urllib3/util/connection.py", line 73, in create_connection
    sock.connect(sa)
ConnectionRefusedError: [Errno 111] Connection refused

The above exception was the direct cause of the following exception:

Traceback (most recent call last):
  File "/home/tthau/.local/lib/python3.10/site-packages/urllib3/connectionpool.py", line 789, in urlopen
    response = self._make_request(
  File "/home/tthau/.local/lib/python3.10/site-packages/urllib3/connectionpool.py", line 495, in _make_request
    conn.request(
  File "/home/tthau/.local/lib/python3.10/site-packages/urllib3/connection.py", line 398, in request
    self.endheaders()
  File "/usr/lib/python3.10/http/client.py", line 1278, in endheaders
    self._send_output(message_body, encode_chunked=encode_chunked)
  File "/usr/lib/python3.10/http/client.py", line 1038, in _send_output
    self.send(msg)
  File "/usr/lib/python3.10/http/client.py", line 976, in send
    self.connect()
  File "/home/tthau/.local/lib/python3.10/site-packages/urllib3/connection.py", line 236, in connect
    self.sock = self._new_conn()
  File "/home/tthau/.local/lib/python3.10/site-packages/urllib3/connection.py", line 211, in _new_conn
    raise NewConnectionError(
urllib3.exceptions.NewConnectionError: <urllib3.connection.HTTPConnection object at 0x7e37fa2ffd00>: Failed to establish a new connection: [Errno 111] Connection refused

The above exception was the direct cause of the following exception:

Traceback (most recent call last):
  File "/home/tthau/PROJECT/BKGGPT/clone_album.py", line 334, in <module>
    all_inputs = driver.find_elements(By.TAG_NAME, "input")
  File "/home/tthau/.local/lib/python3.10/site-packages/selenium/webdriver/remote/webdriver.py", line 936, in find_elements
    return self.execute(Command.FIND_ELEMENTS, {"using": by, "value": value})["value"] or []
  File "/home/tthau/.local/lib/python3.10/site-packages/selenium/webdriver/remote/webdriver.py", line 427, in execute
    response = self.command_executor.execute(driver_command, params)
  File "/home/tthau/.local/lib/python3.10/site-packages/selenium/webdriver/remote/remote_connection.py", line 404, in execute
    return self._request(command_info[0], url, body=data)
  File "/home/tthau/.local/lib/python3.10/site-packages/selenium/webdriver/remote/remote_connection.py", line 428, in _request
    response = self._conn.request(method, url, body=body, headers=headers, timeout=self._client_config.timeout)
  File "/home/tthau/.local/lib/python3.10/site-packages/urllib3/_request_methods.py", line 144, in request
    return self.request_encode_body(
  File "/home/tthau/.local/lib/python3.10/site-packages/urllib3/_request_methods.py", line 279, in request_encode_body
    return self.urlopen(method, url, **extra_kw)
  File "/home/tthau/.local/lib/python3.10/site-packages/urllib3/poolmanager.py", line 443, in urlopen
    response = conn.urlopen(method, u.request_uri, **kw)
  File "/home/tthau/.local/lib/python3.10/site-packages/urllib3/connectionpool.py", line 873, in urlopen
    return self.urlopen(
  File "/home/tthau/.local/lib/python3.10/site-packages/urllib3/connectionpool.py", line 873, in urlopen
    return self.urlopen(
  File "/home/tthau/.local/lib/python3.10/site-packages/urllib3/connectionpool.py", line 873, in urlopen
    return self.urlopen(
  File "/home/tthau/.local/lib/python3.10/site-packages/urllib3/connectionpool.py", line 843, in urlopen
    retries = retries.increment(
  File "/home/tthau/.local/lib/python3.10/site-packages/urllib3/util/retry.py", line 519, in increment
    raise MaxRetryError(_pool, url, reason) from reason  # type: ignore[arg-type]
urllib3.exceptions.MaxRetryError: HTTPConnectionPool(host='localhost', port=51409): Max retries exceeded with url: /session/632eb28b7f4e58ec994bd8f5cf420fc0/elements (Caused by NewConnectionError('<urllib3.connection.HTTPConnection object at 0x7e37fa2ffd00>: Failed to establish a new connection: [Errno 111] Connection refused'))

During handling of the above exception, another exception occurred:

Traceback (most recent call last):
  File "/home/tthau/.local/lib/python3.10/site-packages/urllib3/connection.py", line 196, in _new_conn
    sock = connection.create_connection(
  File "/home/tthau/.local/lib/python3.10/site-packages/urllib3/util/connection.py", line 85, in create_connection
    raise err
  File "/home/tthau/.local/lib/python3.10/site-packages/urllib3/util/connection.py", line 73, in create_connection
    sock.connect(sa)
ConnectionRefusedError: [Errno 111] Connection refused

The above exception was the direct cause of the following exception:

Traceback (most recent call last):
  File "/home/tthau/.local/lib/python3.10/site-packages/urllib3/connectionpool.py", line 789, in urlopen
    response = self._make_request(
  File "/home/tthau/.local/lib/python3.10/site-packages/urllib3/connectionpool.py", line 495, in _make_request
    conn.request(
  File "/home/tthau/.local/lib/python3.10/site-packages/urllib3/connection.py", line 398, in request
    self.endheaders()
  File "/usr/lib/python3.10/http/client.py", line 1278, in endheaders
    self._send_output(message_body, encode_chunked=encode_chunked)
  File "/usr/lib/python3.10/http/client.py", line 1038, in _send_output
    self.send(msg)
  File "/usr/lib/python3.10/http/client.py", line 976, in send
    self.connect()
  File "/home/tthau/.local/lib/python3.10/site-packages/urllib3/connection.py", line 236, in connect
    self.sock = self._new_conn()
  File "/home/tthau/.local/lib/python3.10/site-packages/urllib3/connection.py", line 211, in _new_conn
    raise NewConnectionError(
urllib3.exceptions.NewConnectionError: <urllib3.connection.HTTPConnection object at 0x7e37fa17c430>: Failed to establish a new connection: [Errno 111] Connection refused

The above exception was the direct cause of the following exception:

Traceback (most recent call last):
  File "/home/tthau/PROJECT/BKGGPT/clone_album.py", line 410, in <module>
    driver.save_screenshot("password_input_error.png")
  File "/home/tthau/.local/lib/python3.10/site-packages/selenium/webdriver/remote/webdriver.py", line 994, in save_screenshot
    return self.get_screenshot_as_file(filename)
  File "/home/tthau/.local/lib/python3.10/site-packages/selenium/webdriver/remote/webdriver.py", line 969, in get_screenshot_as_file
    png = self.get_screenshot_as_png()
  File "/home/tthau/.local/lib/python3.10/site-packages/selenium/webdriver/remote/webdriver.py", line 1003, in get_screenshot_as_png
    return b64decode(self.get_screenshot_as_base64().encode("ascii"))
  File "/home/tthau/.local/lib/python3.10/site-packages/selenium/webdriver/remote/webdriver.py", line 1013, in get_screenshot_as_base64
    return self.execute(Command.SCREENSHOT)["value"]
  File "/home/tthau/.local/lib/python3.10/site-packages/selenium/webdriver/remote/webdriver.py", line 427, in execute
    response = self.command_executor.execute(driver_command, params)
  File "/home/tthau/.local/lib/python3.10/site-packages/selenium/webdriver/remote/remote_connection.py", line 404, in execute
    return self._request(command_info[0], url, body=data)
  File "/home/tthau/.local/lib/python3.10/site-packages/selenium/webdriver/remote/remote_connection.py", line 428, in _request
    response = self._conn.request(method, url, body=body, headers=headers, timeout=self._client_config.timeout)
  File "/home/tthau/.local/lib/python3.10/site-packages/urllib3/_request_methods.py", line 136, in request
    return self.request_encode_url(
  File "/home/tthau/.local/lib/python3.10/site-packages/urllib3/_request_methods.py", line 183, in request_encode_url
    return self.urlopen(method, url, **extra_kw)
  File "/home/tthau/.local/lib/python3.10/site-packages/urllib3/poolmanager.py", line 443, in urlopen
    response = conn.urlopen(method, u.request_uri, **kw)
  File "/home/tthau/.local/lib/python3.10/site-packages/urllib3/connectionpool.py", line 873, in urlopen
    return self.urlopen(
  File "/home/tthau/.local/lib/python3.10/site-packages/urllib3/connectionpool.py", line 873, in urlopen
    return self.urlopen(
  File "/home/tthau/.local/lib/python3.10/site-packages/urllib3/connectionpool.py", line 873, in urlopen
    return self.urlopen(
  File "/home/tthau/.local/lib/python3.10/site-packages/urllib3/connectionpool.py", line 843, in urlopen
    retries = retries.increment(
  File "/home/tthau/.local/lib/python3.10/site-packages/urllib3/util/retry.py", line 519, in increment
    raise MaxRetryError(_pool, url, reason) from reason  # type: ignore[arg-type]
urllib3.exceptions.MaxRetryError: HTTPConnectionPool(host='localhost', port=51409): Max retries exceeded with url: /session/632eb28b7f4e58ec994bd8f5cf420fc0/screenshot (Caused by NewConnectionError('<urllib3.connection.HTTPConnection object at 0x7e37fa17c430>: Failed to establish a new connection: [Errno 111] Connection refused'))

2025-04-04 16:02:51,414 - WARNING - Retrying (Retry(total=2, connect=None, read=None, redirect=None, status=None)) after connection broken by 'NewConnectionError('<urllib3.connection.HTTPConnection object at 0x7e37fa17ca00>: Failed to establish a new connection: [Errno 111] Connection refused')': /session/632eb28b7f4e58ec994bd8f5cf420fc0/screenshot
2025-04-04 16:02:51,414 - WARNING - Retrying (Retry(total=1, connect=None, read=None, redirect=None, status=None)) after connection broken by 'NewConnectionError('<urllib3.connection.HTTPConnection object at 0x7e37fa17ca60>: Failed to establish a new connection: [Errno 111] Connection refused')': /session/632eb28b7f4e58ec994bd8f5cf420fc0/screenshot
2025-04-04 16:02:51,415 - WARNING - Retrying (Retry(total=0, connect=None, read=None, redirect=None, status=None)) after connection broken by 'NewConnectionError('<urllib3.connection.HTTPConnection object at 0x7e37fa17cbb0>: Failed to establish a new connection: [Errno 111] Connection refused')': /session/632eb28b7f4e58ec994bd8f5cf420fc0/screenshot
2025-04-04 16:02:51,416 - WARNING - Retrying (Retry(total=2, connect=None, read=None, redirect=None, status=None)) after connection broken by 'NewConnectionError('<urllib3.connection.HTTPConnection object at 0x7e37fa2fd090>: Failed to establish a new connection: [Errno 111] Connection refused')': /session/632eb28b7f4e58ec994bd8f5cf420fc0
2025-04-04 16:02:51,417 - WARNING - Retrying (Retry(total=1, connect=None, read=None, redirect=None, status=None)) after connection broken by 'NewConnectionError('<urllib3.connection.HTTPConnection object at 0x7e37fa17ce50>: Failed to establish a new connection: [Errno 111] Connection refused')': /session/632eb28b7f4e58ec994bd8f5cf420fc0
2025-04-04 16:02:51,417 - WARNING - Retrying (Retry(total=0, connect=None, read=None, redirect=None, status=None)) after connection broken by 'NewConnectionError('<urllib3.connection.HTTPConnection object at 0x7e37fa17cfa0>: Failed to establish a new connection: [Errno 111] Connection refused')': /session/632eb28b7f4e58ec994bd8f5cf420fc0
2025-04-04 16:02:51,419 - INFO - Đã đóng WebDriver
